Workbook

Sheet MASTER
B1: 2026 TEST Campaign Execution Summary | K1: 현재 모두 dummy날짜입니다 | M1: 12 | N1: =M1+1 -> 13 | O1: =N1+1 -> 14 | P1: =O1+1 -> 15 | Q1: =P1+1 -> 16 | R1: =Q1+1 -> 17 | S1: =R1+1 -> 18 | T1: =S1+1 -> 19 | U1: =T1+1 -> 20
G2: 최소/최대날짜: | H2: =TEXT(MIN(H5:H201),"yyyy-mm-dd") -> 2026-01-09 | I2: =TEXT(MAX(I5:I201),"yyyy-mm-dd") -> 2026-10-18 | K2: =TEXT(MIN(K5:K201),"yyyy-mm-dd") -> 2025-03-04 | L2: =TEXT(MAX(L5:L201),"yyyy-mm-dd") -> 2025-10-18 | N2: 함수로 RAW_URL,PageName에서 호출 | W2: Sort by tier | AB2: 최소/최대날짜: | AC2: =TEXT(MIN(AC5:AC201),"yyyy-mm-dd") -> 2026-01-09 | AD2: =TEXT(MAX(AD5:AD201),"yyyy-mm-dd") -> 2026-10-18 | AE2: 컷은 api용csv시트에서 설정합니다.
D3: {="고객법인일정파일 대비 없는 법인: "&IFERROR(_xlfn.TEXTJOIN(", ",1,_xlfn._xlws.FILTER(고객법인일정파일!C4:C200,고객법인일정파일!U4:U200="사용 안됨")),"없음")} -> 고객법인일정파일 대비 없는 법인: TotUl, TotUl, TotUl, TotUl, TotUl, TotUl, TotUl, XADWU (UfricU_ADN), XADWU (UfricU_FR), XADADU, TotUl, TotUl, TotUl, 한총 | H3: This Year | I3: This Year | J3: O표시하면 제외시킵니다. | K3: Last Year | L3: Last Year | N3: This Year | O3: This Year | P3: This Year | Q3: Last Year | R3: Last Year | S3: Last Year | AC3: This Year | AD3: This Year | AE3: This Year
B4: Tier | C4: Region | D4: Subs | E4: COUNTRY | F4: RS | G4: Site Code | H4: Start Date | I4: End Date | J4: api수기제외 | K4: Start Date | L4: End Date | M4: 고객Note | N4: URL | O4: Page Name | P4: Note | Q4: URL | R4: Page Name | S4: Note | U4: Region_#(Appendix정렬용) | W4: Tier | X4: RHQ | Y4: Subs | Z4: COUNTRY | AA4: RS | AB4: site_code | AC4: start_date | AD4: end_date | AE4: end_date(컷)
B5: =IF($G5="","",IFERROR(VLOOKUP($G5,RAW_tier!$B$2:$C$200,2,0),2)) -> 2 | C5: =IF(ISBLANK(태깅기획site_code!F4),"",태깅기획site_code!C4) -> MENA | D5: =IF(ISBLANK(태깅기획site_code!F4),"",IF(고객법인일정파일!P4="한총","SEC",IF(LEN(TRIM(고객법인일정파일!P4))=0,태깅기획site_code!D4,고객법인일정파일!P4))) -> XGAD | E5: =IF(ISBLANK(태깅기획site_code!F4),"",태깅기획site_code!E4) -> UAE | F5: =IF(ISBLANK(태깅기획site_code!F4),"",태깅기획site_code!J4) -> UAE | G5: =IF(ISBLANK(태깅기획site_code!B4),"",태깅기획site_code!F4) -> ae | H5: =IF(ISBLANK(태깅기획site_code!F4),"",IF(고객법인일정파일!Q4="X","X",고객법인일정파일!R4)) -> TBC | I5: =IF(ISBLANK(태깅기획site_code!F4),"",IF(고객법인일정파일!Q4="X","",고객법인일정파일!S4)) -> TBC | K5: =IFERROR(H5-365,"TBD") -> TBD | L5: =IFERROR(I5-365,"TBD") -> TBD | M5: =IF($D5="","",VLOOKUP($D5,고객법인일정파일!$C$5:$J$200,8,0))&"" -> Note1-test XADBN-NL | N5: {=_xlfn.TEXTJOIN(CHAR(10), 1, _xlfn._xlws.FILTER('RAW_URL,PageName'!D$2:D$999, ('RAW_URL,PageName'!$C$2:$C$999=$G5)*('RAW_URL,PageName'!$B$2:$B$999="TY"), ""))} | O5: {=_xlfn.TEXTJOIN(CHAR(10), 1, _xlfn._xlws.FILTER('RAW_URL,PageName'!E$2:E$999, ('RAW_URL,PageName'!$C$2:$C$999=$G5)*('RAW_URL,PageName'!$B$2:$B$999="TY"), ""))} | P5: {=_xlfn.TEXTJOIN(CHAR(10), 1, _xlfn._xlws.FILTER('RAW_URL,PageName'!F$2:F$999, ('RAW_URL,PageName'!$C$2:$C$999=$G5)*('RAW_URL,PageName'!$B$2:$B$999="TY"), ""))} | Q5: {=_xlfn.TEXTJOIN(CHAR(10), 1, _xlfn._xlws.FILTER('RAW_URL,PageName'!D$2:D$999, ('RAW_URL,PageName'!$C$2:$C$999=$G5)*('RAW_URL,PageName'!$B$2:$B$999="LY"), ""))} | R5: {=_xlfn.TEXTJOIN(CHAR(10), 1, _xlfn._xlws.FILTER('RAW_URL,PageName'!E$2:E$999, ('RAW_URL,PageName'!$C$2:$C$999=$G5)*('RAW_URL,PageName'!$B$2:$B$999="LY"), ""))} | S5: {=_xlfn.TEXTJOIN(CHAR(10), 1, _xlfn._xlws.FILTER('RAW_URL,PageName'!F$2:F$999, ('RAW_URL,PageName'!$C$2:$C$999=$G5)*('RAW_URL,PageName'!$B$2:$B$999="LY"), ""))} | U5: =IFERROR(VLOOKUP($C5,태깅기획site_code!$N$4:$O$18,2,0),"") -> 6 | W5: {=_xlfn._xlws.SORT(_xlfn.UNIQUE(_xlfn._xlws.FILTER(B5:I201,(F5:F201<>"")*(H5:H201<>"")*(J5:J201<>"O"))),1,1)} -> 1 | X5: L.America | Y5: XADDU | Z5: Brazil | AA5: Brazil | AB5: br | AC5: 46042 | AD5: 46063 | AE5: =IF(AD5="","",IF(IF(AD5>api용!D$2,api용!D$2,AD5)<AC5,"",IF(AD5>api용!D$2,api용!D$2,AD5))) -> 46063
B6: =IF($G6="","",IFERROR(VLOOKUP($G6,RAW_tier!$B$2:$C$200,2,0),2)) -> 2 | C6: =IF(ISBLANK(태깅기획site_code!F5),"",태깅기획site_code!C5) -> MENA | D6: =IF(ISBLANK(태깅기획site_code!F5),"",IF(고객법인일정파일!P5="한총","SEC",IF(LEN(TRIM(고객법인일정파일!P5))=0,태깅기획site_code!D5,고객법인일정파일!P5))) -> XGAD | E6: =IF(ISBLANK(태깅기획site_code!F5),"",태깅기획site_code!E5) -> UAE | F6: =IF(ISBLANK(태깅기획site_code!F5),"",태깅기획site_code!J5) -> UAE (ar) | G6: =IF(ISBLANK(태깅기획site_code!B5),"",태깅기획site_code!F5) -> ae_ar | H6: =IF(ISBLANK(태깅기획site_code!F5),"",IF(고객법인일정파일!Q5="X","X",고객법인일정파일!R5)) -> TBC | I6: =IF(ISBLANK(태깅기획site_code!F5),"",IF(고객법인일정파일!Q5="X","",고객법인일정파일!S5)) -> TBC | K6: TBD | L6: TBD | M6: =IF(D6="","",VLOOKUP(D6,고객법인일정파일!$C$5:$J$200,8,0))&"" -> Note1-test XADBN-NL | N6: {=_xlfn.TEXTJOIN(CHAR(10), 1, _xlfn._xlws.FILTER('RAW_URL,PageName'!D$2:D$999, ('RAW_URL,PageName'!$C$2:$C$999=$G6)*('RAW_URL,PageName'!$B$2:$B$999="TY"), ""))} | O6: {=_xlfn.TEXTJOIN(CHAR(10), 1, _xlfn._xlws.FILTER('RAW_URL,PageName'!E$2:E$999, ('RAW_URL,PageName'!$C$2:$C$999=$G6)*('RAW_URL,PageName'!$B$2:$B$999="TY"), ""))} | P6: {=_xlfn.TEXTJOIN(CHAR(10), 1, _xlfn._xlws.FILTER('RAW_URL,PageName'!F$2:F$999, ('RAW_URL,PageName'!$C$2:$C$999=$G6)*('RAW_URL,PageName'!$B$2:$B$999="TY"), ""))} | Q6: {=_xlfn.TEXTJOIN(CHAR(10), 1, _xlfn._xlws.FILTER('RAW_URL,PageName'!D$2:D$999, ('RAW_URL,PageName'!$C$2:$C$999=$G6)*('RAW_URL,PageName'!$B$2:$B$999="LY"), ""))} | R6: {=_xlfn.TEXTJOIN(CHAR(10), 1, _xlfn._xlws.FILTER('RAW_URL,PageName'!E$2:E$999, ('RAW_URL,PageName'!$C$2:$C$999=$G6)*('RAW_URL,PageName'!$B$2:$B$999="LY"), ""))} | S6: {=_xlfn.TEXTJOIN(CHAR(10), 1, _xlfn._xlws.FILTER('RAW_URL,PageName'!F$2:F$999, ('RAW_URL,PageName'!$C$2:$C$999=$G6)*('RAW_URL,PageName'!$B$2:$B$999="LY"), ""))} | U6: =IFERROR(VLOOKUP($C6,태깅기획site_code!$N$4:$O$18,2,0),"") -> 6 | W6: 1 | X6: China | Y6: XCIC | Z6: China | AA6: China | AB6: cn | AC6: 46054 | AD6: 46063 | AE6: =IF(AD6="","",IF(IF(AD6>api용!D$2,api용!D$2,AD6)<AC6,"",IF(AD6>api용!D$2,api용!D$2,AD6))) -> 46063
B7: =IF($G7="","",IFERROR(VLOOKUP($G7,RAW_tier!$B$2:$C$200,2,0),2)) -> 2 | C7: =IF(ISBLANK(태깅기획site_code!F6),"",태깅기획site_code!C6) -> Africa | D7: =IF(ISBLANK(태깅기획site_code!F6),"",IF(고객법인일정파일!P6="한총","SEC",IF(LEN(TRIM(고객법인일정파일!P6))=0,태깅기획site_code!D6,고객법인일정파일!P6))) -> XADWU | E7: =IF(ISBLANK(태깅기획site_code!F6),"",태깅기획site_code!E6) -> Africa Pan | F7: =IF(ISBLANK(태깅기획site_code!F6),"",태깅기획site_code!J6) -> AFRICA (en) | G7: =IF(ISBLANK(태깅기획site_code!B6),"",태깅기획site_code!F6) -> africa_en | H7: =IF(ISBLANK(태깅기획site_code!F6),"",IF(고객법인일정파일!Q6="X","X",고객법인일정파일!R6)) | I7: =IF(ISBLANK(태깅기획site_code!F6),"",IF(고객법인일정파일!Q6="X","",고객법인일정파일!S6)) | K7: 45767 | L7: 45790 | M7: =IF(D7="","",VLOOKUP(D7,고객법인일정파일!$C$5:$J$200,8,0))&"" -> #N/A | N7: {=_xlfn.TEXTJOIN(CHAR(10), 1, _xlfn._xlws.FILTER('RAW_URL,PageName'!D$2:D$999, ('RAW_URL,PageName'!$C$2:$C$999=$G7)*('RAW_URL,PageName'!$B$2:$B$999="TY"), ""))} | O7: {=_xlfn.TEXTJOIN(CHAR(10), 1, _xlfn._xlws.FILTER('RAW_URL,PageName'!E$2:E$999, ('RAW_URL,PageName'!$C$2:$C$999=$G7)*('RAW_URL,PageName'!$B$2:$B$999="TY"), ""))} | P7: {=_xlfn.TEXTJOIN(CHAR(10), 1, _xlfn._xlws.FILTER('RAW_URL,PageName'!F$2:F$999, ('RAW_URL,PageName'!$C$2:$C$999=$G7)*('RAW_URL,PageName'!$B$2:$B$999="TY"), ""))} | Q7: {=_xlfn.TEXTJOIN(CHAR(10), 1, _xlfn._xlws.FILTER('RAW_URL,PageName'!D$2:D$999, ('RAW_URL,PageName'!$C$2:$C$999=$G7)*('RAW_URL,PageName'!$B$2:$B$999="LY"), ""))} | R7: {=_xlfn.TEXTJOIN(CHAR(10), 1, _xlfn._xlws.FILTER('RAW_URL,PageName'!E$2:E$999, ('RAW_URL,PageName'!$C$2:$C$999=$G7)*('RAW_URL,PageName'!$B$2:$B$999="LY"), ""))} | S7: {=_xlfn.TEXTJOIN(CHAR(10), 1, _xlfn._xlws.FILTER('RAW_URL,PageName'!F$2:F$999, ('RAW_URL,PageName'!$C$2:$C$999=$G7)*('RAW_URL,PageName'!$B$2:$B$999="LY"), ""))} | U7: =IFERROR(VLOOKUP($C7,태깅기획site_code!$N$4:$O$18,2,0),"") -> 8 | W7: 1 | X7: EU | Y7: XADF | Z7: France | AA7: France | AB7: fr | AC7: 46071 | AD7: 46081 | AE7: =IF(AD7="","",IF(IF(AD7>api용!D$2,api용!D$2,AD7)<AC7,"",IF(AD7>api용!D$2,api용!D$2,AD7))) -> 46081
B8: =IF($G8="","",IFERROR(VLOOKUP($G8,RAW_tier!$B$2:$C$200,2,0),2)) -> 2 | C8: =IF(ISBLANK(태깅기획site_code!F7),"",태깅기획site_code!C7) -> Africa | D8: =IF(ISBLANK(태깅기획site_code!F7),"",IF(고객법인일정파일!P7="한총","SEC",IF(LEN(TRIM(고객법인일정파일!P7))=0,태깅기획site_code!D7,고객법인일정파일!P7))) -> XADWU | E8: =IF(ISBLANK(태깅기획site_code!F7),"",태깅기획site_code!E7) -> Africa Pan | F8: =IF(ISBLANK(태깅기획site_code!F7),"",태깅기획site_code!J7) -> AFRICA (fr) | G8: =IF(ISBLANK(태깅기획site_code!B7),"",태깅기획site_code!F7) -> africa_fr | H8: =IF(ISBLANK(태깅기획site_code!F7),"",IF(고객법인일정파일!Q7="X","X",고객법인일정파일!R7)) | I8: =IF(ISBLANK(태깅기획site_code!F7),"",IF(고객법인일정파일!Q7="X","",고객법인일정파일!S7)) | K8: 45767 | L8: 45787 | M8: =IF(D8="","",VLOOKUP(D8,고객법인일정파일!$C$5:$J$200,8,0))&"" -> #N/A | N8: {=_xlfn.TEXTJOIN(CHAR(10), 1, _xlfn._xlws.FILTER('RAW_URL,PageName'!D$2:D$999, ('RAW_URL,PageName'!$C$2:$C$999=$G8)*('RAW_URL,PageName'!$B$2:$B$999="TY"), ""))} | O8: {=_xlfn.TEXTJOIN(CHAR(10), 1, _xlfn._xlws.FILTER('RAW_URL,PageName'!E$2:E$999, ('RAW_URL,PageName'!$C$2:$C$999=$G8)*('RAW_URL,PageName'!$B$2:$B$999="TY"), ""))} | P8: {=_xlfn.TEXTJOIN(CHAR(10), 1, _xlfn._xlws.FILTER('RAW_URL,PageName'!F$2:F$999, ('RAW_URL,PageName'!$C$2:$C$999=$G8)*('RAW_URL,PageName'!$B$2:$B$999="TY"), ""))} | Q8: {=_xlfn.TEXTJOIN(CHAR(10), 1, _xlfn._xlws.FILTER('RAW_URL,PageName'!D$2:D$999, ('RAW_URL,PageName'!$C$2:$C$999=$G8)*('RAW_URL,PageName'!$B$2:$B$999="LY"), ""))} | R8: {=_xlfn.TEXTJOIN(CHAR(10), 1, _xlfn._xlws.FILTER('RAW_URL,PageName'!E$2:E$999, ('RAW_URL,PageName'!$C$2:$C$999=$G8)*('RAW_URL,PageName'!$B$2:$B$999="LY"), ""))} | S8: {=_xlfn.TEXTJOIN(CHAR(10), 1, _xlfn._xlws.FILTER('RAW_URL,PageName'!F$2:F$999, ('RAW_URL,PageName'!$C$2:$C$999=$G8)*('RAW_URL,PageName'!$B$2:$B$999="LY"), ""))} | U8: =IFERROR(VLOOKUP($C8,태깅기획site_code!$N$4:$O$18,2,0),"") -> 8 | W8: 1 | X8: Japan | Y8: XADJ | Z8: Japan | AA8: Japan | AB8: jp | AC8: X | AE8: =IF(AD8="","",IF(IF(AD8>api용!D$2,api용!D$2,AD8)<AC8,"",IF(AD8>api용!D$2,api용!D$2,AD8)))
B9: =IF($G9="","",IFERROR(VLOOKUP($G9,RAW_tier!$B$2:$C$200,2,0),2)) -> 2 | C9: =IF(ISBLANK(태깅기획site_code!F8),"",태깅기획site_code!C8) -> Africa | D9: =IF(ISBLANK(태깅기획site_code!F8),"",IF(고객법인일정파일!P8="한총","SEC",IF(LEN(TRIM(고객법인일정파일!P8))=0,태깅기획site_code!D8,고객법인일정파일!P8))) -> XADWU | E9: =IF(ISBLANK(태깅기획site_code!F8),"",태깅기획site_code!E8) -> Africa Pan | F9: =IF(ISBLANK(태깅기획site_code!F8),"",태깅기획site_code!J8) -> AFRICA (pt) | G9: =IF(ISBLANK(태깅기획site_code!B8),"",태깅기획site_code!F8) -> africa_pt | H9: =IF(ISBLANK(태깅기획site_code!F8),"",IF(고객법인일정파일!Q8="X","X",고객법인일정파일!R8)) | I9: =IF(ISBLANK(태깅기획site_code!F8),"",IF(고객법인일정파일!Q8="X","",고객법인일정파일!S8)) | K9: TBD | L9: TBD | M9: =IF(D9="","",VLOOKUP(D9,고객법인일정파일!$C$5:$J$200,8,0))&"" -> #N/A | N9: {=_xlfn.TEXTJOIN(CHAR(10), 1, _xlfn._xlws.FILTER('RAW_URL,PageName'!D$2:D$999, ('RAW_URL,PageName'!$C$2:$C$999=$G9)*('RAW_URL,PageName'!$B$2:$B$999="TY"), ""))} | O9: {=_xlfn.TEXTJOIN(CHAR(10), 1, _xlfn._xlws.FILTER('RAW_URL,PageName'!E$2:E$999, ('RAW_URL,PageName'!$C$2:$C$999=$G9)*('RAW_URL,PageName'!$B$2:$B$999="TY"), ""))} | P9: {=_xlfn.TEXTJOIN(CHAR(10), 1, _xlfn._xlws.FILTER('RAW_URL,PageName'!F$2:F$999, ('RAW_URL,PageName'!$C$2:$C$999=$G9)*('RAW_URL,PageName'!$B$2:$B$999="TY"), ""))} | Q9: {=_xlfn.TEXTJOIN(CHAR(10), 1, _xlfn._xlws.FILTER('RAW_URL,PageName'!D$2:D$999, ('RAW_URL,PageName'!$C$2:$C$999=$G9)*('RAW_URL,PageName'!$B$2:$B$999="LY"), ""))} | R9: {=_xlfn.TEXTJOIN(CHAR(10), 1, _xlfn._xlws.FILTER('RAW_URL,PageName'!E$2:E$999, ('RAW_URL,PageName'!$C$2:$C$999=$G9)*('RAW_URL,PageName'!$B$2:$B$999="LY"), ""))} | S9: {=_xlfn.TEXTJOIN(CHAR(10), 1, _xlfn._xlws.FILTER('RAW_URL,PageName'!F$2:F$999, ('RAW_URL,PageName'!$C$2:$C$999=$G9)*('RAW_URL,PageName'!$B$2:$B$999="LY"), ""))} | U9: =IFERROR(VLOOKUP($C9,태깅기획site_code!$N$4:$O$18,2,0),"") -> 8 | W9: 1 | X9: L.America | Y9: XADM | Z9: Mexico | AA9: Mexico | AB9: mx | AC9: 46042 | AD9: 46063 | AE9: =IF(AD9="","",IF(IF(AD9>api용!D$2,api용!D$2,AD9)<AC9,"",IF(AD9>api용!D$2,api용!D$2,AD9))) -> 46063
B10: =IF($G10="","",IFERROR(VLOOKUP($G10,RAW_tier!$B$2:$C$200,2,0),2)) -> 2 | C10: =IF(ISBLANK(태깅기획site_code!F9),"",태깅기획site_code!C9) -> EU | D10: =IF(ISBLANK(태깅기획site_code!F9),"",IF(고객법인일정파일!P9="한총","SEC",IF(LEN(TRIM(고객법인일정파일!P9))=0,태깅기획site_code!D9,고객법인일정파일!P9))) -> XADUD | E10: =IF(ISBLANK(태깅기획site_code!F9),"",태깅기획site_code!E9) -> Albania | F10: =IF(ISBLANK(태깅기획site_code!F9),"",태깅기획site_code!J9) -> Albania | G10: =IF(ISBLANK(태깅기획site_code!B9),"",태깅기획site_code!F9) -> al | H10: =IF(ISBLANK(태깅기획site_code!F9),"",IF(고객법인일정파일!Q9="X","X",고객법인일정파일!R9)) -> X | I10: =IF(ISBLANK(태깅기획site_code!F9),"",IF(고객법인일정파일!Q9="X","",고객법인일정파일!S9)) | K10: TBD | L10: TBD | M10: =IF(D10="","",VLOOKUP(D10,고객법인일정파일!$C$5:$J$200,8,0))&"" -> Note1-test XADUX-UT | N10: {=_xlfn.TEXTJOIN(CHAR(10), 1, _xlfn._xlws.FILTER('RAW_URL,PageName'!D$2:D$999, ('RAW_URL,PageName'!$C$2:$C$999=$G10)*('RAW_URL,PageName'!$B$2:$B$999="TY"), ""))} | O10: {=_xlfn.TEXTJOIN(CHAR(10), 1, _xlfn._xlws.FILTER('RAW_URL,PageName'!E$2:E$999, ('RAW_URL,PageName'!$C$2:$C$999=$G10)*('RAW_URL,PageName'!$B$2:$B$999="TY"), ""))} | P10: {=_xlfn.TEXTJOIN(CHAR(10), 1, _xlfn._xlws.FILTER('RAW_URL,PageName'!F$2:F$999, ('RAW_URL,PageName'!$C$2:$C$999=$G10)*('RAW_URL,PageName'!$B$2:$B$999="TY"), ""))} | Q10: {=_xlfn.TEXTJOIN(CHAR(10), 1, _xlfn._xlws.FILTER('RAW_URL,PageName'!D$2:D$999, ('RAW_URL,PageName'!$C$2:$C$999=$G10)*('RAW_URL,PageName'!$B$2:$B$999="LY"), ""))} | R10: {=_xlfn.TEXTJOIN(CHAR(10), 1, _xlfn._xlws.FILTER('RAW_URL,PageName'!E$2:E$999, ('RAW_URL,PageName'!$C$2:$C$999=$G10)*('RAW_URL,PageName'!$B$2:$B$999="LY"), ""))} | S10: {=_xlfn.TEXTJOIN(CHAR(10), 1, _xlfn._xlws.FILTER('RAW_URL,PageName'!F$2:F$999, ('RAW_URL,PageName'!$C$2:$C$999=$G10)*('RAW_URL,PageName'!$B$2:$B$999="LY"), ""))} | U10: =IFERROR(VLOOKUP($C10,태깅기획site_code!$N$4:$O$18,2,0),"") -> 2 | W10: 1 | X10: MENA | Y10: XADTK | Z10: Turkey | AA10: Turkey | AB10: tr | AC10: 46054 | AD10: 46063 | AE10: =IF(AD10="","",IF(IF(AD10>api용!D$2,api용!D$2,AD10)<AC10,"",IF(AD10>api용!D$2,api용!D$2,AD10))) -> 46063
B11: =IF($G11="","",IFERROR(VLOOKUP($G11,RAW_tier!$B$2:$C$200,2,0),2)) -> 2 | C11: =IF(ISBLANK(태깅기획site_code!F10),"",태깅기획site_code!C10) -> L.America | D11: =IF(ISBLANK(태깅기획site_code!F10),"",IF(고객법인일정파일!P10="한총","SEC",IF(LEN(TRIM(고객법인일정파일!P10))=0,태깅기획site_code!D10,고객법인일정파일!P10))) -> XADUXU | E11: =IF(ISBLANK(태깅기획site_code!F10),"",태깅기획site_code!E10) -> Argentina | F11: =IF(ISBLANK(태깅기획site_code!F10),"",태깅기획site_code!J10) -> Argentina | G11: =IF(ISBLANK(태깅기획site_code!B10),"",태깅기획site_code!F10) -> ar | H11: =IF(ISBLANK(태깅기획site_code!F10),"",IF(고객법인일정파일!Q10="X","X",고객법인일정파일!R10)) -> 46297 | I11: =IF(ISBLANK(태깅기획site_code!F10),"",IF(고객법인일정파일!Q10="X","",고객법인일정파일!S10)) -> 46313 | K11: 45935 | L11: 45948 | M11: =IF(D11="","",VLOOKUP(D11,고객법인일정파일!$C$5:$J$200,8,0))&"" -> Note1-test XMAD | N11: {=_xlfn.TEXTJOIN(CHAR(10), 1, _xlfn._xlws.FILTER('RAW_URL,PageName'!D$2:D$999, ('RAW_URL,PageName'!$C$2:$C$999=$G11)*('RAW_URL,PageName'!$B$2:$B$999="TY"), ""))} | O11: {=_xlfn.TEXTJOIN(CHAR(10), 1, _xlfn._xlws.FILTER('RAW_URL,PageName'!E$2:E$999, ('RAW_URL,PageName'!$C$2:$C$999=$G11)*('RAW_URL,PageName'!$B$2:$B$999="TY"), ""))} | P11: {=_xlfn.TEXTJOIN(CHAR(10), 1, _xlfn._xlws.FILTER('RAW_URL,PageName'!F$2:F$999, ('RAW_URL,PageName'!$C$2:$C$999=$G11)*('RAW_URL,PageName'!$B$2:$B$999="TY"), ""))} | Q11: {=_xlfn.TEXTJOIN(CHAR(10), 1, _xlfn._xlws.FILTER('RAW_URL,PageName'!D$2:D$999, ('RAW_URL,PageName'!$C$2:$C$999=$G11)*('RAW_URL,PageName'!$B$2:$B$999="LY"), ""))} | R11: {=_xlfn.TEXTJOIN(CHAR(10), 1, _xlfn._xlws.FILTER('RAW_URL,PageName'!E$2:E$999, ('RAW_URL,PageName'!$C$2:$C$999=$G11)*('RAW_URL,PageName'!$B$2:$B$999="LY"), ""))} | S11: {=_xlfn.TEXTJOIN(CHAR(10), 1, _xlfn._xlws.FILTER('RAW_URL,PageName'!F$2:F$999, ('RAW_URL,PageName'!$C$2:$C$999=$G11)*('RAW_URL,PageName'!$B$2:$B$999="LY"), ""))} | U11: =IFERROR(VLOOKUP($C11,태깅기획site_code!$N$4:$O$18,2,0),"") -> 3 | W11: 1 | X11: EU | Y11: XADUK | Z11: UK | AA11: UK | AB11: uk | AC11: X | AE11: =IF(AD11="","",IF(IF(AD11>api용!D$2,api용!D$2,AD11)<AC11,"",IF(AD11>api용!D$2,api용!D$2,AD11)))
B12: =IF($G12="","",IFERROR(VLOOKUP($G12,RAW_tier!$B$2:$C$200,2,0),2)) -> 2 | C12: =IF(ISBLANK(태깅기획site_code!F11),"",태깅기획site_code!C11) -> EU | D12: =IF(ISBLANK(태깅기획site_code!F11),"",IF(고객법인일정파일!P11="한총","SEC",IF(LEN(TRIM(고객법인일정파일!P11))=0,태깅기획site_code!D11,고객법인일정파일!P11))) -> XADUX-UT | E12: =IF(ISBLANK(태깅기획site_code!F11),"",태깅기획site_code!E11) -> Austria | F12: =IF(ISBLANK(태깅기획site_code!F11),"",태깅기획site_code!J11) -> Austria | G12: =IF(ISBLANK(태깅기획site_code!B11),"",태깅기획site_code!F11) -> at | H12: =IF(ISBLANK(태깅기획site_code!F11),"",IF(고객법인일정파일!Q11="X","X",고객법인일정파일!R11)) -> 46042 | I12: =IF(ISBLANK(태깅기획site_code!F11),"",IF(고객법인일정파일!Q11="X","",고객법인일정파일!S11)) -> 46064 | K12: 45767 | L12: 45788 | M12: =IF(D12="","",VLOOKUP(D12,고객법인일정파일!$C$5:$J$200,8,0))&"" -> Note1-test XADUX-UT | N12: {=_xlfn.TEXTJOIN(CHAR(10), 1, _xlfn._xlws.FILTER('RAW_URL,PageName'!D$2:D$999, ('RAW_URL,PageName'!$C$2:$C$999=$G12)*('RAW_URL,PageName'!$B$2:$B$999="TY"), ""))} | O12: {=_xlfn.TEXTJOIN(CHAR(10), 1, _xlfn._xlws.FILTER('RAW_URL,PageName'!E$2:E$999, ('RAW_URL,PageName'!$C$2:$C$999=$G12)*('RAW_URL,PageName'!$B$2:$B$999="TY"), ""))} | P12: {=_xlfn.TEXTJOIN(CHAR(10), 1, _xlfn._xlws.FILTER('RAW_URL,PageName'!F$2:F$999, ('RAW_URL,PageName'!$C$2:$C$999=$G12)*('RAW_URL,PageName'!$B$2:$B$999="TY"), ""))} | Q12: {=_xlfn.TEXTJOIN(CHAR(10), 1, _xlfn._xlws.FILTER('RAW_URL,PageName'!D$2:D$999, ('RAW_URL,PageName'!$C$2:$C$999=$G12)*('RAW_URL,PageName'!$B$2:$B$999="LY"), ""))} | R12: {=_xlfn.TEXTJOIN(CHAR(10), 1, _xlfn._xlws.FILTER('RAW_URL,PageName'!E$2:E$999, ('RAW_URL,PageName'!$C$2:$C$999=$G12)*('RAW_URL,PageName'!$B$2:$B$999="LY"), ""))} | S12: {=_xlfn.TEXTJOIN(CHAR(10), 1, _xlfn._xlws.FILTER('RAW_URL,PageName'!F$2:F$999, ('RAW_URL,PageName'!$C$2:$C$999=$G12)*('RAW_URL,PageName'!$B$2:$B$999="LY"), ""))} | U12: =IFERROR(VLOOKUP($C12,태깅기획site_code!$N$4:$O$18,2,0),"") -> 2 | W12: 1 | X12: N.America | Y12: XADU | Z12: USA | AA12: US NEW | AB12: us | AC12: 46042 | AD12: 46063 | AE12: =IF(AD12="","",IF(IF(AD12>api용!D$2,api용!D$2,AD12)<AC12,"",IF(AD12>api용!D$2,api용!D$2,AD12))) -> 46063
B13: =IF($G13="","",IFERROR(VLOOKUP($G13,RAW_tier!$B$2:$C$200,2,0),2)) -> 2 | C13: =IF(ISBLANK(태깅기획site_code!F12),"",태깅기획site_code!C12) -> S.E.Asia | D13: =IF(ISBLANK(태깅기획site_code!F12),"",IF(고객법인일정파일!P12="한총","SEC",IF(LEN(TRIM(고객법인일정파일!P12))=0,태깅기획site_code!D12,고객법인일정파일!P12))) -> XADUU | E13: =IF(ISBLANK(태깅기획site_code!F12),"",태깅기획site_code!E12) -> Australia | F13: =IF(ISBLANK(태깅기획site_code!F12),"",태깅기획site_code!J12) -> Australia | G13: =IF(ISBLANK(태깅기획site_code!B12),"",태깅기획site_code!F12) -> au | H13: =IF(ISBLANK(태깅기획site_code!F12),"",IF(고객법인일정파일!Q12="X","X",고객법인일정파일!R12)) -> 46046 | I13: =IF(ISBLANK(태깅기획site_code!F12),"",IF(고객법인일정파일!Q12="X","",고객법인일정파일!S12)) -> 46067 | K13: 45770 | L13: 45790 | M13: =IF(D13="","",VLOOKUP(D13,고객법인일정파일!$C$5:$J$200,8,0))&"" | N13: {=_xlfn.TEXTJOIN(CHAR(10), 1, _xlfn._xlws.FILTER('RAW_URL,PageName'!D$2:D$999, ('RAW_URL,PageName'!$C$2:$C$999=$G13)*('RAW_URL,PageName'!$B$2:$B$999="TY"), ""))} | O13: {=_xlfn.TEXTJOIN(CHAR(10), 1, _xlfn._xlws.FILTER('RAW_URL,PageName'!E$2:E$999, ('RAW_URL,PageName'!$C$2:$C$999=$G13)*('RAW_URL,PageName'!$B$2:$B$999="TY"), ""))} | P13: {=_xlfn.TEXTJOIN(CHAR(10), 1, _xlfn._xlws.FILTER('RAW_URL,PageName'!F$2:F$999, ('RAW_URL,PageName'!$C$2:$C$999=$G13)*('RAW_URL,PageName'!$B$2:$B$999="TY"), ""))} | Q13: {=_xlfn.TEXTJOIN(CHAR(10), 1, _xlfn._xlws.FILTER('RAW_URL,PageName'!D$2:D$999, ('RAW_URL,PageName'!$C$2:$C$999=$G13)*('RAW_URL,PageName'!$B$2:$B$999="LY"), ""))} | R13: {=_xlfn.TEXTJOIN(CHAR(10), 1, _xlfn._xlws.FILTER('RAW_URL,PageName'!E$2:E$999, ('RAW_URL,PageName'!$C$2:$C$999=$G13)*('RAW_URL,PageName'!$B$2:$B$999="LY"), ""))} | S13: {=_xlfn.TEXTJOIN(CHAR(10), 1, _xlfn._xlws.FILTER('RAW_URL,PageName'!F$2:F$999, ('RAW_URL,PageName'!$C$2:$C$999=$G13)*('RAW_URL,PageName'!$B$2:$B$999="LY"), ""))} | U13: =IFERROR(VLOOKUP($C13,태깅기획site_code!$N$4:$O$18,2,0),"") -> 4 | W13: 2 | X13: MENA | Y13: XGAD | Z13: UAE | AA13: UAE | AB13: ae | AC13: TBC | AD13: TBC | AE13: =IF(AD13="","",IF(IF(AD13>api용!D$2,api용!D$2,AD13)<AC13,"",IF(AD13>api용!D$2,api용!D$2,AD13)))
B14: =IF($G14="","",IFERROR(VLOOKUP($G14,RAW_tier!$B$2:$C$200,2,0),2)) -> 2 | C14: =IF(ISBLANK(태깅기획site_code!F13),"",태깅기획site_code!C13) -> CIS | D14: =IF(ISBLANK(태깅기획site_code!F13),"",IF(고객법인일정파일!P13="한총","SEC",IF(LEN(TRIM(고객법인일정파일!P13))=0,태깅기획site_code!D13,고객법인일정파일!P13))) -> XADRC | E14: =IF(ISBLANK(태깅기획site_code!F13),"",태깅기획site_code!E13) -> Azerbaijan | F14: =IF(ISBLANK(태깅기획site_code!F13),"",태깅기획site_code!J13) -> Azerbaijan | G14: =IF(ISBLANK(태깅기획site_code!B13),"",태깅기획site_code!F13) -> az | H14: =IF(ISBLANK(태깅기획site_code!F13),"",IF(고객법인일정파일!Q13="X","X",고객법인일정파일!R13)) | I14: =IF(ISBLANK(태깅기획site_code!F13),"",IF(고객법인일정파일!Q13="X","",고객법인일정파일!S13)) | K14: TBD | L14: TBD | M14: =IF(D14="","",VLOOKUP(D14,고객법인일정파일!$C$5:$J$200,8,0))&"" -> #N/A | N14: {=_xlfn.TEXTJOIN(CHAR(10), 1, _xlfn._xlws.FILTER('RAW_URL,PageName'!D$2:D$999, ('RAW_URL,PageName'!$C$2:$C$999=$G14)*('RAW_URL,PageName'!$B$2:$B$999="TY"), ""))} | O14: {=_xlfn.TEXTJOIN(CHAR(10), 1, _xlfn._xlws.FILTER('RAW_URL,PageName'!E$2:E$999, ('RAW_URL,PageName'!$C$2:$C$999=$G14)*('RAW_URL,PageName'!$B$2:$B$999="TY"), ""))} | P14: {=_xlfn.TEXTJOIN(CHAR(10), 1, _xlfn._xlws.FILTER('RAW_URL,PageName'!F$2:F$999, ('RAW_URL,PageName'!$C$2:$C$999=$G14)*('RAW_URL,PageName'!$B$2:$B$999="TY"), ""))} | Q14: {=_xlfn.TEXTJOIN(CHAR(10), 1, _xlfn._xlws.FILTER('RAW_URL,PageName'!D$2:D$999, ('RAW_URL,PageName'!$C$2:$C$999=$G14)*('RAW_URL,PageName'!$B$2:$B$999="LY"), ""))} | R14: {=_xlfn.TEXTJOIN(CHAR(10), 1, _xlfn._xlws.FILTER('RAW_URL,PageName'!E$2:E$999, ('RAW_URL,PageName'!$C$2:$C$999=$G14)*('RAW_URL,PageName'!$B$2:$B$999="LY"), ""))} | S14: {=_xlfn.TEXTJOIN(CHAR(10), 1, _xlfn._xlws.FILTER('RAW_URL,PageName'!F$2:F$999, ('RAW_URL,PageName'!$C$2:$C$999=$G14)*('RAW_URL,PageName'!$B$2:$B$999="LY"), ""))} | U14: =IFERROR(VLOOKUP($C14,태깅기획site_code!$N$4:$O$18,2,0),"") -> 7 | W14: 2 | X14: MENA | Y14: XGAD | Z14: UAE | AA14: UAE (ar) | AB14: ae_ar | AC14: TBC | AD14: TBC | AE14: =IF(AD14="","",IF(IF(AD14>api용!D$2,api용!D$2,AD14)<AC14,"",IF(AD14>api용!D$2,api용!D$2,AD14)))
B15: =IF($G15="","",IFERROR(VLOOKUP($G15,RAW_tier!$B$2:$C$200,2,0),2)) -> 2 | C15: =IF(ISBLANK(태깅기획site_code!F14),"",태깅기획site_code!C14) -> EU | D15: =IF(ISBLANK(태깅기획site_code!F14),"",IF(고객법인일정파일!P14="한총","SEC",IF(LEN(TRIM(고객법인일정파일!P14))=0,태깅기획site_code!D14,고객법인일정파일!P14))) -> XADUD | E15: =IF(ISBLANK(태깅기획site_code!F14),"",태깅기획site_code!E14) -> Bosnia | F15: =IF(ISBLANK(태깅기획site_code!F14),"",태깅기획site_code!J14) -> Bosnia | G15: =IF(ISBLANK(태깅기획site_code!B14),"",태깅기획site_code!F14) -> ba | H15: =IF(ISBLANK(태깅기획site_code!F14),"",IF(고객법인일정파일!Q14="X","X",고객법인일정파일!R14)) -> X | I15: =IF(ISBLANK(태깅기획site_code!F14),"",IF(고객법인일정파일!Q14="X","",고객법인일정파일!S14)) | K15: TBD | L15: TBD | M15: =IF(D15="","",VLOOKUP(D15,고객법인일정파일!$C$5:$J$200,8,0))&"" -> Note1-test XADUX-UT | N15: {=_xlfn.TEXTJOIN(CHAR(10), 1, _xlfn._xlws.FILTER('RAW_URL,PageName'!D$2:D$999, ('RAW_URL,PageName'!$C$2:$C$999=$G15)*('RAW_URL,PageName'!$B$2:$B$999="TY"), ""))} | O15: {=_xlfn.TEXTJOIN(CHAR(10), 1, _xlfn._xlws.FILTER('RAW_URL,PageName'!E$2:E$999, ('RAW_URL,PageName'!$C$2:$C$999=$G15)*('RAW_URL,PageName'!$B$2:$B$999="TY"), ""))} | P15: {=_xlfn.TEXTJOIN(CHAR(10), 1, _xlfn._xlws.FILTER('RAW_URL,PageName'!F$2:F$999, ('RAW_URL,PageName'!$C$2:$C$999=$G15)*('RAW_URL,PageName'!$B$2:$B$999="TY"), ""))} | Q15: {=_xlfn.TEXTJOIN(CHAR(10), 1, _xlfn._xlws.FILTER('RAW_URL,PageName'!D$2:D$999, ('RAW_URL,PageName'!$C$2:$C$999=$G15)*('RAW_URL,PageName'!$B$2:$B$999="LY"), ""))} | R15: {=_xlfn.TEXTJOIN(CHAR(10), 1, _xlfn._xlws.FILTER('RAW_URL,PageName'!E$2:E$999, ('RAW_URL,PageName'!$C$2:$C$999=$G15)*('RAW_URL,PageName'!$B$2:$B$999="LY"), ""))} | S15: {=_xlfn.TEXTJOIN(CHAR(10), 1, _xlfn._xlws.FILTER('RAW_URL,PageName'!F$2:F$999, ('RAW_URL,PageName'!$C$2:$C$999=$G15)*('RAW_URL,PageName'!$B$2:$B$999="LY"), ""))} | U15: =IFERROR(VLOOKUP($C15,태깅기획site_code!$N$4:$O$18,2,0),"") -> 2 | W15: 2 | X15: EU | Y15: XADUD | Z15: Albania | AA15: Albania | AB15: al | AC15: X | AE15: =IF(AD15="","",IF(IF(AD15>api용!D$2,api용!D$2,AD15)<AC15,"",IF(AD15>api용!D$2,api용!D$2,AD15)))
B16: =IF($G16="","",IFERROR(VLOOKUP($G16,RAW_tier!$B$2:$C$200,2,0),2)) -> 2 | C16: =IF(ISBLANK(태깅기획site_code!F15),"",태깅기획site_code!C15) -> S.W.Asia | D16: =IF(ISBLANK(태깅기획site_code!F15),"",IF(고객법인일정파일!P15="한총","SEC",IF(LEN(TRIM(고객법인일정파일!P15))=0,태깅기획site_code!D15,고객법인일정파일!P15))) -> XIADL | E16: =IF(ISBLANK(태깅기획site_code!F15),"",태깅기획site_code!E15) -> Bangladesh | F16: =IF(ISBLANK(태깅기획site_code!F15),"",태깅기획site_code!J15) -> Bangladesh | G16: =IF(ISBLANK(태깅기획site_code!B15),"",태깅기획site_code!F15) -> bd | H16: =IF(ISBLANK(태깅기획site_code!F15),"",IF(고객법인일정파일!Q15="X","X",고객법인일정파일!R15)) -> 46038 | I16: =IF(ISBLANK(태깅기획site_code!F15),"",IF(고객법인일정파일!Q15="X","",고객법인일정파일!S15)) -> 46044 | K16: 45764 | L16: 45775 | M16: =IF(D16="","",VLOOKUP(D16,고객법인일정파일!$C$5:$J$200,8,0))&"" | N16: {=_xlfn.TEXTJOIN(CHAR(10), 1, _xlfn._xlws.FILTER('RAW_URL,PageName'!D$2:D$999, ('RAW_URL,PageName'!$C$2:$C$999=$G16)*('RAW_URL,PageName'!$B$2:$B$999="TY"), ""))} | O16: {=_xlfn.TEXTJOIN(CHAR(10), 1, _xlfn._xlws.FILTER('RAW_URL,PageName'!E$2:E$999, ('RAW_URL,PageName'!$C$2:$C$999=$G16)*('RAW_URL,PageName'!$B$2:$B$999="TY"), ""))} | P16: {=_xlfn.TEXTJOIN(CHAR(10), 1, _xlfn._xlws.FILTER('RAW_URL,PageName'!F$2:F$999, ('RAW_URL,PageName'!$C$2:$C$999=$G16)*('RAW_URL,PageName'!$B$2:$B$999="TY"), ""))} | Q16: {=_xlfn.TEXTJOIN(CHAR(10), 1, _xlfn._xlws.FILTER('RAW_URL,PageName'!D$2:D$999, ('RAW_URL,PageName'!$C$2:$C$999=$G16)*('RAW_URL,PageName'!$B$2:$B$999="LY"), ""))} | R16: {=_xlfn.TEXTJOIN(CHAR(10), 1, _xlfn._xlws.FILTER('RAW_URL,PageName'!E$2:E$999, ('RAW_URL,PageName'!$C$2:$C$999=$G16)*('RAW_URL,PageName'!$B$2:$B$999="LY"), ""))} | S16: {=_xlfn.TEXTJOIN(CHAR(10), 1, _xlfn._xlws.FILTER('RAW_URL,PageName'!F$2:F$999, ('RAW_URL,PageName'!$C$2:$C$999=$G16)*('RAW_URL,PageName'!$B$2:$B$999="LY"), ""))} | U16: =IFERROR(VLOOKUP($C16,태깅기획site_code!$N$4:$O$18,2,0),"") -> 5 | W16: 2 | X16: L.America | Y16: XADUXU | Z16: Argentina | AA16: Argentina | AB16: ar | AC16: 46297 | AD16: 46313 | AE16: =IF(AD16="","",IF(IF(AD16>api용!D$2,api용!D$2,AD16)<AC16,"",IF(AD16>api용!D$2,api용!D$2,AD16)))
B17: =IF($G17="","",IFERROR(VLOOKUP($G17,RAW_tier!$B$2:$C$200,2,0),2)) -> 2 | C17: =IF(ISBLANK(태깅기획site_code!F16),"",태깅기획site_code!C16) -> EU | D17: =IF(ISBLANK(태깅기획site_code!F16),"",IF(고객법인일정파일!P16="한총","SEC",IF(LEN(TRIM(고객법인일정파일!P16))=0,태깅기획site_code!D16,고객법인일정파일!P16))) -> XADBN-BE | E17: =IF(ISBLANK(태깅기획site_code!F16),"",태깅기획site_code!E16) -> Belgium | F17: =IF(ISBLANK(태깅기획site_code!F16),"",태깅기획site_code!J16) -> Belgium(NL) | G17: =IF(ISBLANK(태깅기획site_code!B16),"",태깅기획site_code!F16) -> be | H17: =IF(ISBLANK(태깅기획site_code!F16),"",IF(고객법인일정파일!Q16="X","X",고객법인일정파일!R16)) -> 46050 | I17: =IF(ISBLANK(태깅기획site_code!F16),"",IF(고객법인일정파일!Q16="X","",고객법인일정파일!S16)) -> 46063 | K17: 45774 | L17: 45780 | M17: =IF(D17="","",VLOOKUP(D17,고객법인일정파일!$C$5:$J$200,8,0))&"" | N17: {=_xlfn.TEXTJOIN(CHAR(10), 1, _xlfn._xlws.FILTER('RAW_URL,PageName'!D$2:D$999, ('RAW_URL,PageName'!$C$2:$C$999=$G17)*('RAW_URL,PageName'!$B$2:$B$999="TY"), ""))} | O17: {=_xlfn.TEXTJOIN(CHAR(10), 1, _xlfn._xlws.FILTER('RAW_URL,PageName'!E$2:E$999, ('RAW_URL,PageName'!$C$2:$C$999=$G17)*('RAW_URL,PageName'!$B$2:$B$999="TY"), ""))} | P17: {=_xlfn.TEXTJOIN(CHAR(10), 1, _xlfn._xlws.FILTER('RAW_URL,PageName'!F$2:F$999, ('RAW_URL,PageName'!$C$2:$C$999=$G17)*('RAW_URL,PageName'!$B$2:$B$999="TY"), ""))} | Q17: {=_xlfn.TEXTJOIN(CHAR(10), 1, _xlfn._xlws.FILTER('RAW_URL,PageName'!D$2:D$999, ('RAW_URL,PageName'!$C$2:$C$999=$G17)*('RAW_URL,PageName'!$B$2:$B$999="LY"), ""))} | R17: {=_xlfn.TEXTJOIN(CHAR(10), 1, _xlfn._xlws.FILTER('RAW_URL,PageName'!E$2:E$999, ('RAW_URL,PageName'!$C$2:$C$999=$G17)*('RAW_URL,PageName'!$B$2:$B$999="LY"), ""))} | S17: {=_xlfn.TEXTJOIN(CHAR(10), 1, _xlfn._xlws.FILTER('RAW_URL,PageName'!F$2:F$999, ('RAW_URL,PageName'!$C$2:$C$999=$G17)*('RAW_URL,PageName'!$B$2:$B$999="LY"), ""))} | U17: =IFERROR(VLOOKUP($C17,태깅기획site_code!$N$4:$O$18,2,0),"") -> 2 | W17: 2 | X17: EU | Y17: XADUX-UT | Z17: Austria | AA17: Austria | AB17: at | AC17: 46042 | AD17: 46064 | AE17: =IF(AD17="","",IF(IF(AD17>api용!D$2,api용!D$2,AD17)<AC17,"",IF(AD17>api용!D$2,api용!D$2,AD17))) -> 46064
B18: =IF($G18="","",IFERROR(VLOOKUP($G18,RAW_tier!$B$2:$C$200,2,0),2)) -> 2 | C18: =IF(ISBLANK(태깅기획site_code!F17),"",태깅기획site_code!C17) -> EU | D18: =IF(ISBLANK(태깅기획site_code!F17),"",IF(고객법인일정파일!P17="한총","SEC",IF(LEN(TRIM(고객법인일정파일!P17))=0,태깅기획site_code!D17,고객법인일정파일!P17))) -> XADBN-BE | E18: =IF(ISBLANK(태깅기획site_code!F17),"",태깅기획site_code!E17) -> Belgium | F18: =IF(ISBLANK(태깅기획site_code!F17),"",태깅기획site_code!J17) -> Belgium(NL) | G18: =IF(ISBLANK(태깅기획site_code!B17),"",태깅기획site_code!F17) -> be_fr | H18: =IF(ISBLANK(태깅기획site_code!F17),"",IF(고객법인일정파일!Q17="X","X",고객법인일정파일!R17)) -> 46050 | I18: =IF(ISBLANK(태깅기획site_code!F17),"",IF(고객법인일정파일!Q17="X","",고객법인일정파일!S17)) -> 46063 | J18: O | K18: 45774 | L18: 45780 | M18: =IF(D18="","",VLOOKUP(D18,고객법인일정파일!$C$5:$J$200,8,0))&"" | N18: {=_xlfn.TEXTJOIN(CHAR(10), 1, _xlfn._xlws.FILTER('RAW_URL,PageName'!D$2:D$999, ('RAW_URL,PageName'!$C$2:$C$999=$G18)*('RAW_URL,PageName'!$B$2:$B$999="TY"), ""))} | O18: {=_xlfn.TEXTJOIN(CHAR(10), 1, _xlfn._xlws.FILTER('RAW_URL,PageName'!E$2:E$999, ('RAW_URL,PageName'!$C$2:$C$999=$G18)*('RAW_URL,PageName'!$B$2:$B$999="TY"), ""))} | P18: {=_xlfn.TEXTJOIN(CHAR(10), 1, _xlfn._xlws.FILTER('RAW_URL,PageName'!F$2:F$999, ('RAW_URL,PageName'!$C$2:$C$999=$G18)*('RAW_URL,PageName'!$B$2:$B$999="TY"), ""))} | Q18: {=_xlfn.TEXTJOIN(CHAR(10), 1, _xlfn._xlws.FILTER('RAW_URL,PageName'!D$2:D$999, ('RAW_URL,PageName'!$C$2:$C$999=$G18)*('RAW_URL,PageName'!$B$2:$B$999="LY"), ""))} | R18: {=_xlfn.TEXTJOIN(CHAR(10), 1, _xlfn._xlws.FILTER('RAW_URL,PageName'!E$2:E$999, ('RAW_URL,PageName'!$C$2:$C$999=$G18)*('RAW_URL,PageName'!$B$2:$B$999="LY"), ""))} | S18: {=_xlfn.TEXTJOIN(CHAR(10), 1, _xlfn._xlws.FILTER('RAW_URL,PageName'!F$2:F$999, ('RAW_URL,PageName'!$C$2:$C$999=$G18)*('RAW_URL,PageName'!$B$2:$B$999="LY"), ""))} | U18: =IFERROR(VLOOKUP($C18,태깅기획site_code!$N$4:$O$18,2,0),"") -> 2 | W18: 2 | X18: S.E.Asia | Y18: XADUU | Z18: Australia | AA18: Australia | AB18: au | AC18: 46046 | AD18: 46067 | AE18: =IF(AD18="","",IF(IF(AD18>api용!D$2,api용!D$2,AD18)<AC18,"",IF(AD18>api용!D$2,api용!D$2,AD18))) -> 46067
B19: =IF($G19="","",IFERROR(VLOOKUP($G19,RAW_tier!$B$2:$C$200,2,0),2)) -> 2 | C19: =IF(ISBLANK(태깅기획site_code!F18),"",태깅기획site_code!C18) -> EU | D19: =IF(ISBLANK(태깅기획site_code!F18),"",IF(고객법인일정파일!P18="한총","SEC",IF(LEN(TRIM(고객법인일정파일!P18))=0,태깅기획site_code!D18,고객법인일정파일!P18))) -> XADROM | E19: =IF(ISBLANK(태깅기획site_code!F18),"",태깅기획site_code!E18) -> Bulgaria | F19: =IF(ISBLANK(태깅기획site_code!F18),"",태깅기획site_code!J18) -> Bulgaria | G19: =IF(ISBLANK(태깅기획site_code!B18),"",태깅기획site_code!F18) -> bg | H19: =IF(ISBLANK(태깅기획site_code!F18),"",IF(고객법인일정파일!Q18="X","X",고객법인일정파일!R18)) -> 46113 | I19: =IF(ISBLANK(태깅기획site_code!F18),"",IF(고객법인일정파일!Q18="X","",고객법인일정파일!S18)) -> 46122 | M19: =IF(D19="","",VLOOKUP(D19,고객법인일정파일!$C$5:$J$200,8,0))&"" -> Note1-test XADROM | N19: {=_xlfn.TEXTJOIN(CHAR(10), 1, _xlfn._xlws.FILTER('RAW_URL,PageName'!D$2:D$999, ('RAW_URL,PageName'!$C$2:$C$999=$G19)*('RAW_URL,PageName'!$B$2:$B$999="TY"), ""))} | O19: {=_xlfn.TEXTJOIN(CHAR(10), 1, _xlfn._xlws.FILTER('RAW_URL,PageName'!E$2:E$999, ('RAW_URL,PageName'!$C$2:$C$999=$G19)*('RAW_URL,PageName'!$B$2:$B$999="TY"), ""))} | P19: {=_xlfn.TEXTJOIN(CHAR(10), 1, _xlfn._xlws.FILTER('RAW_URL,PageName'!F$2:F$999, ('RAW_URL,PageName'!$C$2:$C$999=$G19)*('RAW_URL,PageName'!$B$2:$B$999="TY"), ""))} | Q19: {=_xlfn.TEXTJOIN(CHAR(10), 1, _xlfn._xlws.FILTER('RAW_URL,PageName'!D$2:D$999, ('RAW_URL,PageName'!$C$2:$C$999=$G19)*('RAW_URL,PageName'!$B$2:$B$999="LY"), ""))} | R19: {=_xlfn.TEXTJOIN(CHAR(10), 1, _xlfn._xlws.FILTER('RAW_URL,PageName'!E$2:E$999, ('RAW_URL,PageName'!$C$2:$C$999=$G19)*('RAW_URL,PageName'!$B$2:$B$999="LY"), ""))} | S19: {=_xlfn.TEXTJOIN(CHAR(10), 1, _xlfn._xlws.FILTER('RAW_URL,PageName'!F$2:F$999, ('RAW_URL,PageName'!$C$2:$C$999=$G19)*('RAW_URL,PageName'!$B$2:$B$999="LY"), ""))} | U19: =IFERROR(VLOOKUP($C19,태깅기획site_code!$N$4:$O$18,2,0),"") -> 2 | W19: 2 | X19: EU | Y19: XADUD | Z19: Bosnia | AA19: Bosnia | AB19: ba | AC19: X | AE19: =IF(AD19="","",IF(IF(AD19>api용!D$2,api용!D$2,AD19)<AC19,"",IF(AD19>api용!D$2,api용!D$2,AD19)))
B20: =IF($G20="","",IFERROR(VLOOKUP($G20,RAW_tier!$B$2:$C$200,2,0),2)) -> 1 | C20: =IF(ISBLANK(태깅기획site_code!F19),"",태깅기획site_code!C19) -> L.America | D20: =IF(ISBLANK(태깅기획site_code!F19),"",IF(고객법인일정파일!P19="한총","SEC",IF(LEN(TRIM(고객법인일정파일!P19))=0,태깅기획site_code!D19,고객법인일정파일!P19))) -> XADDU | E20: =IF(ISBLANK(태깅기획site_code!F19),"",태깅기획site_code!E19) -> Brazil | F20: =IF(ISBLANK(태깅기획site_code!F19),"",태깅기획site_code!J19) -> Brazil | G20: =IF(ISBLANK(태깅기획site_code!B19),"",태깅기획site_code!F19) -> br | H20: =IF(ISBLANK(태깅기획site_code!F19),"",IF(고객법인일정파일!Q19="X","X",고객법인일정파일!R19)) -> 46042 | I20: =IF(ISBLANK(태깅기획site_code!F19),"",IF(고객법인일정파일!Q19="X","",고객법인일정파일!S19)) -> 46063 | M20: =IF(D20="","",VLOOKUP(D20,고객법인일정파일!$C$5:$J$200,8,0))&"" | N20: {=_xlfn.TEXTJOIN(CHAR(10), 1, _xlfn._xlws.FILTER('RAW_URL,PageName'!D$2:D$999, ('RAW_URL,PageName'!$C$2:$C$999=$G20)*('RAW_URL,PageName'!$B$2:$B$999="TY"), ""))} | O20: {=_xlfn.TEXTJOIN(CHAR(10), 1, _xlfn._xlws.FILTER('RAW_URL,PageName'!E$2:E$999, ('RAW_URL,PageName'!$C$2:$C$999=$G20)*('RAW_URL,PageName'!$B$2:$B$999="TY"), ""))} | P20: {=_xlfn.TEXTJOIN(CHAR(10), 1, _xlfn._xlws.FILTER('RAW_URL,PageName'!F$2:F$999, ('RAW_URL,PageName'!$C$2:$C$999=$G20)*('RAW_URL,PageName'!$B$2:$B$999="TY"), ""))} | Q20: {=_xlfn.TEXTJOIN(CHAR(10), 1, _xlfn._xlws.FILTER('RAW_URL,PageName'!D$2:D$999, ('RAW_URL,PageName'!$C$2:$C$999=$G20)*('RAW_URL,PageName'!$B$2:$B$999="LY"), ""))} | R20: {=_xlfn.TEXTJOIN(CHAR(10), 1, _xlfn._xlws.FILTER('RAW_URL,PageName'!E$2:E$999, ('RAW_URL,PageName'!$C$2:$C$999=$G20)*('RAW_URL,PageName'!$B$2:$B$999="LY"), ""))} | S20: {=_xlfn.TEXTJOIN(CHAR(10), 1, _xlfn._xlws.FILTER('RAW_URL,PageName'!F$2:F$999, ('RAW_URL,PageName'!$C$2:$C$999=$G20)*('RAW_URL,PageName'!$B$2:$B$999="LY"), ""))} | U20: =IFERROR(VLOOKUP($C20,태깅기획site_code!$N$4:$O$18,2,0),"") -> 3 | W20: 2 | X20: S.W.Asia | Y20: XIADL | Z20: Bangladesh | AA20: Bangladesh | AB20: bd | AC20: 46038 | AD20: 46044 | AE20: =IF(AD20="","",IF(IF(AD20>api용!D$2,api용!D$2,AD20)<AC20,"",IF(AD20>api용!D$2,api용!D$2,AD20))) -> 46044
B21: =IF($G21="","",IFERROR(VLOOKUP($G21,RAW_tier!$B$2:$C$200,2,0),2)) -> 2 | C21: =IF(ISBLANK(태깅기획site_code!F20),"",태깅기획site_code!C20) -> N.America | D21: =IF(ISBLANK(태깅기획site_code!F20),"",IF(고객법인일정파일!P20="한총","SEC",IF(LEN(TRIM(고객법인일정파일!P20))=0,태깅기획site_code!D20,고객법인일정파일!P20))) -> XADCU | E21: =IF(ISBLANK(태깅기획site_code!F20),"",태깅기획site_code!E20) -> Canada | F21: =IF(ISBLANK(태깅기획site_code!F20),"",태깅기획site_code!J20) -> Canada | G21: =IF(ISBLANK(태깅기획site_code!B20),"",태깅기획site_code!F20) -> ca | H21: =IF(ISBLANK(태깅기획site_code!F20),"",IF(고객법인일정파일!Q20="X","X",고객법인일정파일!R20)) -> 46043 | I21: =IF(ISBLANK(태깅기획site_code!F20),"",IF(고객법인일정파일!Q20="X","",고객법인일정파일!S20)) -> 46063 | M21: =IF(D21="","",VLOOKUP(D21,고객법인일정파일!$C$5:$J$200,8,0))&"" | N21: {=_xlfn.TEXTJOIN(CHAR(10), 1, _xlfn._xlws.FILTER('RAW_URL,PageName'!D$2:D$999, ('RAW_URL,PageName'!$C$2:$C$999=$G21)*('RAW_URL,PageName'!$B$2:$B$999="TY"), ""))} | O21: {=_xlfn.TEXTJOIN(CHAR(10), 1, _xlfn._xlws.FILTER('RAW_URL,PageName'!E$2:E$999, ('RAW_URL,PageName'!$C$2:$C$999=$G21)*('RAW_URL,PageName'!$B$2:$B$999="TY"), ""))} | P21: {=_xlfn.TEXTJOIN(CHAR(10), 1, _xlfn._xlws.FILTER('RAW_URL,PageName'!F$2:F$999, ('RAW_URL,PageName'!$C$2:$C$999=$G21)*('RAW_URL,PageName'!$B$2:$B$999="TY"), ""))} | Q21: {=_xlfn.TEXTJOIN(CHAR(10), 1, _xlfn._xlws.FILTER('RAW_URL,PageName'!D$2:D$999, ('RAW_URL,PageName'!$C$2:$C$999=$G21)*('RAW_URL,PageName'!$B$2:$B$999="LY"), ""))} | R21: {=_xlfn.TEXTJOIN(CHAR(10), 1, _xlfn._xlws.FILTER('RAW_URL,PageName'!E$2:E$999, ('RAW_URL,PageName'!$C$2:$C$999=$G21)*('RAW_URL,PageName'!$B$2:$B$999="LY"), ""))} | S21: {=_xlfn.TEXTJOIN(CHAR(10), 1, _xlfn._xlws.FILTER('RAW_URL,PageName'!F$2:F$999, ('RAW_URL,PageName'!$C$2:$C$999=$G21)*('RAW_URL,PageName'!$B$2:$B$999="LY"), ""))} | U21: =IFERROR(VLOOKUP($C21,태깅기획site_code!$N$4:$O$18,2,0),"") -> 1 | W21: 2 | X21: EU | Y21: XADBN-BE | Z21: Belgium | AA21: Belgium(NL) | AB21: be | AC21: 46050 | AD21: 46063 | AE21: =IF(AD21="","",IF(IF(AD21>api용!D$2,api용!D$2,AD21)<AC21,"",IF(AD21>api용!D$2,api용!D$2,AD21))) -> 46063
B22: =IF($G22="","",IFERROR(VLOOKUP($G22,RAW_tier!$B$2:$C$200,2,0),2)) -> 2 | C22: =IF(ISBLANK(태깅기획site_code!F21),"",태깅기획site_code!C21) -> N.America | D22: =IF(ISBLANK(태깅기획site_code!F21),"",IF(고객법인일정파일!P21="한총","SEC",IF(LEN(TRIM(고객법인일정파일!P21))=0,태깅기획site_code!D21,고객법인일정파일!P21))) -> XADCU | E22: =IF(ISBLANK(태깅기획site_code!F21),"",태깅기획site_code!E21) -> Canada | F22: =IF(ISBLANK(태깅기획site_code!F21),"",태깅기획site_code!J21) -> Canada (fr) | G22: =IF(ISBLANK(태깅기획site_code!B21),"",태깅기획site_code!F21) -> ca_fr | H22: =IF(ISBLANK(태깅기획site_code!F21),"",IF(고객법인일정파일!Q21="X","X",고객법인일정파일!R21)) -> 46043 | I22: =IF(ISBLANK(태깅기획site_code!F21),"",IF(고객법인일정파일!Q21="X","",고객법인일정파일!S21)) -> 46063 | M22: =IF(D22="","",VLOOKUP(D22,고객법인일정파일!$C$5:$J$200,8,0))&"" | N22: {=_xlfn.TEXTJOIN(CHAR(10), 1, _xlfn._xlws.FILTER('RAW_URL,PageName'!D$2:D$999, ('RAW_URL,PageName'!$C$2:$C$999=$G22)*('RAW_URL,PageName'!$B$2:$B$999="TY"), ""))} | O22: {=_xlfn.TEXTJOIN(CHAR(10), 1, _xlfn._xlws.FILTER('RAW_URL,PageName'!E$2:E$999, ('RAW_URL,PageName'!$C$2:$C$999=$G22)*('RAW_URL,PageName'!$B$2:$B$999="TY"), ""))} | P22: {=_xlfn.TEXTJOIN(CHAR(10), 1, _xlfn._xlws.FILTER('RAW_URL,PageName'!F$2:F$999, ('RAW_URL,PageName'!$C$2:$C$999=$G22)*('RAW_URL,PageName'!$B$2:$B$999="TY"), ""))} | Q22: {=_xlfn.TEXTJOIN(CHAR(10), 1, _xlfn._xlws.FILTER('RAW_URL,PageName'!D$2:D$999, ('RAW_URL,PageName'!$C$2:$C$999=$G22)*('RAW_URL,PageName'!$B$2:$B$999="LY"), ""))} | R22: {=_xlfn.TEXTJOIN(CHAR(10), 1, _xlfn._xlws.FILTER('RAW_URL,PageName'!E$2:E$999, ('RAW_URL,PageName'!$C$2:$C$999=$G22)*('RAW_URL,PageName'!$B$2:$B$999="LY"), ""))} | S22: {=_xlfn.TEXTJOIN(CHAR(10), 1, _xlfn._xlws.FILTER('RAW_URL,PageName'!F$2:F$999, ('RAW_URL,PageName'!$C$2:$C$999=$G22)*('RAW_URL,PageName'!$B$2:$B$999="LY"), ""))} | U22: =IFERROR(VLOOKUP($C22,태깅기획site_code!$N$4:$O$18,2,0),"") -> 1 | W22: 2 | X22: EU | Y22: XADROM | Z22: Bulgaria | AA22: Bulgaria | AB22: bg | AC22: 46113 | AD22: 46122 | AE22: =IF(AD22="","",IF(IF(AD22>api용!D$2,api용!D$2,AD22)<AC22,"",IF(AD22>api용!D$2,api용!D$2,AD22)))
B23: =IF($G23="","",IFERROR(VLOOKUP($G23,RAW_tier!$B$2:$C$200,2,0),2)) -> 2 | C23: =IF(ISBLANK(태깅기획site_code!F22),"",태깅기획site_code!C22) -> EU | D23: =IF(ISBLANK(태깅기획site_code!F22),"",IF(고객법인일정파일!P22="한총","SEC",IF(LEN(TRIM(고객법인일정파일!P22))=0,태깅기획site_code!D22,고객법인일정파일!P22))) -> XADUX-CH | E23: =IF(ISBLANK(태깅기획site_code!F22),"",태깅기획site_code!E22) -> Switzerland | F23: =IF(ISBLANK(태깅기획site_code!F22),"",태깅기획site_code!J22) -> Switzerland | G23: =IF(ISBLANK(태깅기획site_code!B22),"",태깅기획site_code!F22) -> ch | H23: =IF(ISBLANK(태깅기획site_code!F22),"",IF(고객법인일정파일!Q22="X","X",고객법인일정파일!R22)) -> 46048 | I23: =IF(ISBLANK(태깅기획site_code!F22),"",IF(고객법인일정파일!Q22="X","",고객법인일정파일!S22)) -> 46063 | M23: =IF(D23="","",VLOOKUP(D23,고객법인일정파일!$C$5:$J$200,8,0))&"" | N23: {=_xlfn.TEXTJOIN(CHAR(10), 1, _xlfn._xlws.FILTER('RAW_URL,PageName'!D$2:D$999, ('RAW_URL,PageName'!$C$2:$C$999=$G23)*('RAW_URL,PageName'!$B$2:$B$999="TY"), ""))} | O23: {=_xlfn.TEXTJOIN(CHAR(10), 1, _xlfn._xlws.FILTER('RAW_URL,PageName'!E$2:E$999, ('RAW_URL,PageName'!$C$2:$C$999=$G23)*('RAW_URL,PageName'!$B$2:$B$999="TY"), ""))} | P23: {=_xlfn.TEXTJOIN(CHAR(10), 1, _xlfn._xlws.FILTER('RAW_URL,PageName'!F$2:F$999, ('RAW_URL,PageName'!$C$2:$C$999=$G23)*('RAW_URL,PageName'!$B$2:$B$999="TY"), ""))} | Q23: {=_xlfn.TEXTJOIN(CHAR(10), 1, _xlfn._xlws.FILTER('RAW_URL,PageName'!D$2:D$999, ('RAW_URL,PageName'!$C$2:$C$999=$G23)*('RAW_URL,PageName'!$B$2:$B$999="LY"), ""))} | R23: {=_xlfn.TEXTJOIN(CHAR(10), 1, _xlfn._xlws.FILTER('RAW_URL,PageName'!E$2:E$999, ('RAW_URL,PageName'!$C$2:$C$999=$G23)*('RAW_URL,PageName'!$B$2:$B$999="LY"), ""))} | S23: {=_xlfn.TEXTJOIN(CHAR(10), 1, _xlfn._xlws.FILTER('RAW_URL,PageName'!F$2:F$999, ('RAW_URL,PageName'!$C$2:$C$999=$G23)*('RAW_URL,PageName'!$B$2:$B$999="LY"), ""))} | U23: =IFERROR(VLOOKUP($C23,태깅기획site_code!$N$4:$O$18,2,0),"") -> 2 | W23: 2 | X23: N.America | Y23: XADCU | Z23: Canada | AA23: Canada | AB23: ca | AC23: 46043 | AD23: 46063 | AE23: =IF(AD23="","",IF(IF(AD23>api용!D$2,api용!D$2,AD23)<AC23,"",IF(AD23>api용!D$2,api용!D$2,AD23))) -> 46063
B24: =IF($G24="","",IFERROR(VLOOKUP($G24,RAW_tier!$B$2:$C$200,2,0),2)) -> 2 | C24: =IF(ISBLANK(태깅기획site_code!F23),"",태깅기획site_code!C23) -> EU | D24: =IF(ISBLANK(태깅기획site_code!F23),"",IF(고객법인일정파일!P23="한총","SEC",IF(LEN(TRIM(고객법인일정파일!P23))=0,태깅기획site_code!D23,고객법인일정파일!P23))) -> XADUX-CH | E24: =IF(ISBLANK(태깅기획site_code!F23),"",태깅기획site_code!E23) -> Switzerland | F24: =IF(ISBLANK(태깅기획site_code!F23),"",태깅기획site_code!J23) -> Switzerland(FR) | G24: =IF(ISBLANK(태깅기획site_code!B23),"",태깅기획site_code!F23) -> ch_fr | H24: =IF(ISBLANK(태깅기획site_code!F23),"",IF(고객법인일정파일!Q23="X","X",고객법인일정파일!R23)) -> 46048 | I24: =IF(ISBLANK(태깅기획site_code!F23),"",IF(고객법인일정파일!Q23="X","",고객법인일정파일!S23)) -> 46063 | M24: =IF(D24="","",VLOOKUP(D24,고객법인일정파일!$C$5:$J$200,8,0))&"" | N24: {=_xlfn.TEXTJOIN(CHAR(10), 1, _xlfn._xlws.FILTER('RAW_URL,PageName'!D$2:D$999, ('RAW_URL,PageName'!$C$2:$C$999=$G24)*('RAW_URL,PageName'!$B$2:$B$999="TY"), ""))} | O24: {=_xlfn.TEXTJOIN(CHAR(10), 1, _xlfn._xlws.FILTER('RAW_URL,PageName'!E$2:E$999, ('RAW_URL,PageName'!$C$2:$C$999=$G24)*('RAW_URL,PageName'!$B$2:$B$999="TY"), ""))} | P24: {=_xlfn.TEXTJOIN(CHAR(10), 1, _xlfn._xlws.FILTER('RAW_URL,PageName'!F$2:F$999, ('RAW_URL,PageName'!$C$2:$C$999=$G24)*('RAW_URL,PageName'!$B$2:$B$999="TY"), ""))} | Q24: {=_xlfn.TEXTJOIN(CHAR(10), 1, _xlfn._xlws.FILTER('RAW_URL,PageName'!D$2:D$999, ('RAW_URL,PageName'!$C$2:$C$999=$G24)*('RAW_URL,PageName'!$B$2:$B$999="LY"), ""))} | R24: {=_xlfn.TEXTJOIN(CHAR(10), 1, _xlfn._xlws.FILTER('RAW_URL,PageName'!E$2:E$999, ('RAW_URL,PageName'!$C$2:$C$999=$G24)*('RAW_URL,PageName'!$B$2:$B$999="LY"), ""))} | S24: {=_xlfn.TEXTJOIN(CHAR(10), 1, _xlfn._xlws.FILTER('RAW_URL,PageName'!F$2:F$999, ('RAW_URL,PageName'!$C$2:$C$999=$G24)*('RAW_URL,PageName'!$B$2:$B$999="LY"), ""))} | U24: =IFERROR(VLOOKUP($C24,태깅기획site_code!$N$4:$O$18,2,0),"") -> 2 | W24: 2 | X24: N.America | Y24: XADCU | Z24: Canada | AA24: Canada (fr) | AB24: ca_fr | AC24: 46043 | AD24: 46063 | AE24: =IF(AD24="","",IF(IF(AD24>api용!D$2,api용!D$2,AD24)<AC24,"",IF(AD24>api용!D$2,api용!D$2,AD24))) -> 46063
B25: =IF($G25="","",IFERROR(VLOOKUP($G25,RAW_tier!$B$2:$C$200,2,0),2)) -> 2 | C25: =IF(ISBLANK(태깅기획site_code!F24),"",태깅기획site_code!C24) -> L.America | D25: =IF(ISBLANK(태깅기획site_code!F24),"",IF(고객법인일정파일!P24="한총","SEC",IF(LEN(TRIM(고객법인일정파일!P24))=0,태깅기획site_code!D24,고객법인일정파일!P24))) -> XADCH | E25: =IF(ISBLANK(태깅기획site_code!F24),"",태깅기획site_code!E24) -> Chile | F25: =IF(ISBLANK(태깅기획site_code!F24),"",태깅기획site_code!J24) -> Chile | G25: =IF(ISBLANK(태깅기획site_code!B24),"",태깅기획site_code!F24) -> cl | H25: =IF(ISBLANK(태깅기획site_code!F24),"",IF(고객법인일정파일!Q24="X","X",고객법인일정파일!R24)) -> 46042 | I25: =IF(ISBLANK(태깅기획site_code!F24),"",IF(고객법인일정파일!Q24="X","",고객법인일정파일!S24)) -> 46063 | M25: =IF(D25="","",VLOOKUP(D25,고객법인일정파일!$C$5:$J$200,8,0))&"" | N25: {=_xlfn.TEXTJOIN(CHAR(10), 1, _xlfn._xlws.FILTER('RAW_URL,PageName'!D$2:D$999, ('RAW_URL,PageName'!$C$2:$C$999=$G25)*('RAW_URL,PageName'!$B$2:$B$999="TY"), ""))} | O25: {=_xlfn.TEXTJOIN(CHAR(10), 1, _xlfn._xlws.FILTER('RAW_URL,PageName'!E$2:E$999, ('RAW_URL,PageName'!$C$2:$C$999=$G25)*('RAW_URL,PageName'!$B$2:$B$999="TY"), ""))} | P25: {=_xlfn.TEXTJOIN(CHAR(10), 1, _xlfn._xlws.FILTER('RAW_URL,PageName'!F$2:F$999, ('RAW_URL,PageName'!$C$2:$C$999=$G25)*('RAW_URL,PageName'!$B$2:$B$999="TY"), ""))} | Q25: {=_xlfn.TEXTJOIN(CHAR(10), 1, _xlfn._xlws.FILTER('RAW_URL,PageName'!D$2:D$999, ('RAW_URL,PageName'!$C$2:$C$999=$G25)*('RAW_URL,PageName'!$B$2:$B$999="LY"), ""))} | R25: {=_xlfn.TEXTJOIN(CHAR(10), 1, _xlfn._xlws.FILTER('RAW_URL,PageName'!E$2:E$999, ('RAW_URL,PageName'!$C$2:$C$999=$G25)*('RAW_URL,PageName'!$B$2:$B$999="LY"), ""))} | S25: {=_xlfn.TEXTJOIN(CHAR(10), 1, _xlfn._xlws.FILTER('RAW_URL,PageName'!F$2:F$999, ('RAW_URL,PageName'!$C$2:$C$999=$G25)*('RAW_URL,PageName'!$B$2:$B$999="LY"), ""))} | U25: =IFERROR(VLOOKUP($C25,태깅기획site_code!$N$4:$O$18,2,0),"") -> 3 | W25: 2 | X25: EU | Y25: XADUX-CH | Z25: Switzerland | AA25: Switzerland | AB25: ch | AC25: 46048 | AD25: 46063 | AE25: =IF(AD25="","",IF(IF(AD25>api용!D$2,api용!D$2,AD25)<AC25,"",IF(AD25>api용!D$2,api용!D$2,AD25))) -> 46063
B26: =IF($G26="","",IFERROR(VLOOKUP($G26,RAW_tier!$B$2:$C$200,2,0),2)) -> 1 | C26: =IF(ISBLANK(태깅기획site_code!F25),"",태깅기획site_code!C25) -> China | D26: =IF(ISBLANK(태깅기획site_code!F25),"",IF(고객법인일정파일!P25="한총","SEC",IF(LEN(TRIM(고객법인일정파일!P25))=0,태깅기획site_code!D25,고객법인일정파일!P25))) -> XCIC | E26: =IF(ISBLANK(태깅기획site_code!F25),"",태깅기획site_code!E25) -> China | F26: =IF(ISBLANK(태깅기획site_code!F25),"",태깅기획site_code!J25) -> China | G26: =IF(ISBLANK(태깅기획site_code!B25),"",태깅기획site_code!F25) -> cn | H26: =IF(ISBLANK(태깅기획site_code!F25),"",IF(고객법인일정파일!Q25="X","X",고객법인일정파일!R25)) -> 46054 | I26: =IF(ISBLANK(태깅기획site_code!F25),"",IF(고객법인일정파일!Q25="X","",고객법인일정파일!S25)) -> 46063 | M26: =IF(D26="","",VLOOKUP(D26,고객법인일정파일!$C$5:$J$200,8,0))&"" -> Note1-test XADHK | N26: {=_xlfn.TEXTJOIN(CHAR(10), 1, _xlfn._xlws.FILTER('RAW_URL,PageName'!D$2:D$999, ('RAW_URL,PageName'!$C$2:$C$999=$G26)*('RAW_URL,PageName'!$B$2:$B$999="TY"), ""))} | O26: {=_xlfn.TEXTJOIN(CHAR(10), 1, _xlfn._xlws.FILTER('RAW_URL,PageName'!E$2:E$999, ('RAW_URL,PageName'!$C$2:$C$999=$G26)*('RAW_URL,PageName'!$B$2:$B$999="TY"), ""))} | P26: {=_xlfn.TEXTJOIN(CHAR(10), 1, _xlfn._xlws.FILTER('RAW_URL,PageName'!F$2:F$999, ('RAW_URL,PageName'!$C$2:$C$999=$G26)*('RAW_URL,PageName'!$B$2:$B$999="TY"), ""))} | Q26: {=_xlfn.TEXTJOIN(CHAR(10), 1, _xlfn._xlws.FILTER('RAW_URL,PageName'!D$2:D$999, ('RAW_URL,PageName'!$C$2:$C$999=$G26)*('RAW_URL,PageName'!$B$2:$B$999="LY"), ""))} | R26: {=_xlfn.TEXTJOIN(CHAR(10), 1, _xlfn._xlws.FILTER('RAW_URL,PageName'!E$2:E$999, ('RAW_URL,PageName'!$C$2:$C$999=$G26)*('RAW_URL,PageName'!$B$2:$B$999="LY"), ""))} | S26: {=_xlfn.TEXTJOIN(CHAR(10), 1, _xlfn._xlws.FILTER('RAW_URL,PageName'!F$2:F$999, ('RAW_URL,PageName'!$C$2:$C$999=$G26)*('RAW_URL,PageName'!$B$2:$B$999="LY"), ""))} | U26: =IFERROR(VLOOKUP($C26,태깅기획site_code!$N$4:$O$18,2,0),"") -> 9 | W26: 2 | X26: EU | Y26: XADUX-CH | Z26: Switzerland | AA26: Switzerland(FR) | AB26: ch_fr | AC26: 46048 | AD26: 46063 | AE26: =IF(AD26="","",IF(IF(AD26>api용!D$2,api용!D$2,AD26)<AC26,"",IF(AD26>api용!D$2,api용!D$2,AD26))) -> 46063
B27: =IF($G27="","",IFERROR(VLOOKUP($G27,RAW_tier!$B$2:$C$200,2,0),2)) -> 2 | C27: =IF(ISBLANK(태깅기획site_code!F26),"",태깅기획site_code!C26) -> L.America | D27: =IF(ISBLANK(태깅기획site_code!F26),"",IF(고객법인일정파일!P26="한총","SEC",IF(LEN(TRIM(고객법인일정파일!P26))=0,태깅기획site_code!D26,고객법인일정파일!P26))) -> XUMCOL | E27: =IF(ISBLANK(태깅기획site_code!F26),"",태깅기획site_code!E26) -> Colombia | F27: =IF(ISBLANK(태깅기획site_code!F26),"",태깅기획site_code!J26) -> Colombia | G27: =IF(ISBLANK(태깅기획site_code!B26),"",태깅기획site_code!F26) -> co | H27: =IF(ISBLANK(태깅기획site_code!F26),"",IF(고객법인일정파일!Q26="X","X",고객법인일정파일!R26)) -> 46042 | I27: =IF(ISBLANK(태깅기획site_code!F26),"",IF(고객법인일정파일!Q26="X","",고객법인일정파일!S26)) -> 46063 | K27: 45767 | L27: 45787 | M27: =IF(D27="","",VLOOKUP(D27,고객법인일정파일!$C$5:$J$200,8,0))&"" | N27: {=_xlfn.TEXTJOIN(CHAR(10), 1, _xlfn._xlws.FILTER('RAW_URL,PageName'!D$2:D$999, ('RAW_URL,PageName'!$C$2:$C$999=$G27)*('RAW_URL,PageName'!$B$2:$B$999="TY"), ""))} | O27: {=_xlfn.TEXTJOIN(CHAR(10), 1, _xlfn._xlws.FILTER('RAW_URL,PageName'!E$2:E$999, ('RAW_URL,PageName'!$C$2:$C$999=$G27)*('RAW_URL,PageName'!$B$2:$B$999="TY"), ""))} | P27: {=_xlfn.TEXTJOIN(CHAR(10), 1, _xlfn._xlws.FILTER('RAW_URL,PageName'!F$2:F$999, ('RAW_URL,PageName'!$C$2:$C$999=$G27)*('RAW_URL,PageName'!$B$2:$B$999="TY"), ""))} | Q27: {=_xlfn.TEXTJOIN(CHAR(10), 1, _xlfn._xlws.FILTER('RAW_URL,PageName'!D$2:D$999, ('RAW_URL,PageName'!$C$2:$C$999=$G27)*('RAW_URL,PageName'!$B$2:$B$999="LY"), ""))} | R27: {=_xlfn.TEXTJOIN(CHAR(10), 1, _xlfn._xlws.FILTER('RAW_URL,PageName'!E$2:E$999, ('RAW_URL,PageName'!$C$2:$C$999=$G27)*('RAW_URL,PageName'!$B$2:$B$999="LY"), ""))} | S27: {=_xlfn.TEXTJOIN(CHAR(10), 1, _xlfn._xlws.FILTER('RAW_URL,PageName'!F$2:F$999, ('RAW_URL,PageName'!$C$2:$C$999=$G27)*('RAW_URL,PageName'!$B$2:$B$999="LY"), ""))} | U27: =IFERROR(VLOOKUP($C27,태깅기획site_code!$N$4:$O$18,2,0),"") -> 3 | W27: 2 | X27: L.America | Y27: XADCH | Z27: Chile | AA27: Chile | AB27: cl | AC27: 46042 | AD27: 46063 | AE27: =IF(AD27="","",IF(IF(AD27>api용!D$2,api용!D$2,AD27)<AC27,"",IF(AD27>api용!D$2,api용!D$2,AD27))) -> 46063
B28: =IF($G28="","",IFERROR(VLOOKUP($G28,RAW_tier!$B$2:$C$200,2,0),2)) -> 2 | C28: =IF(ISBLANK(태깅기획site_code!F27),"",태깅기획site_code!C27) -> EU | D28: =IF(ISBLANK(태깅기획site_code!F27),"",IF(고객법인일정파일!P27="한총","SEC",IF(LEN(TRIM(고객법인일정파일!P27))=0,태깅기획site_code!D27,고객법인일정파일!P27))) -> XADCZ | E28: =IF(ISBLANK(태깅기획site_code!F27),"",태깅기획site_code!E27) -> Czech | F28: =IF(ISBLANK(태깅기획site_code!F27),"",태깅기획site_code!J27) -> Czech | G28: =IF(ISBLANK(태깅기획site_code!B27),"",태깅기획site_code!F27) -> cz | H28: =IF(ISBLANK(태깅기획site_code!F27),"",IF(고객법인일정파일!Q27="X","X",고객법인일정파일!R27)) -> 46054 | I28: =IF(ISBLANK(태깅기획site_code!F27),"",IF(고객법인일정파일!Q27="X","",고객법인일정파일!S27)) -> 46063 | K28: 45778 | L28: 45787 | M28: =IF(D28="","",VLOOKUP(D28,고객법인일정파일!$C$5:$J$200,8,0))&"" | N28: {=_xlfn.TEXTJOIN(CHAR(10), 1, _xlfn._xlws.FILTER('RAW_URL,PageName'!D$2:D$999, ('RAW_URL,PageName'!$C$2:$C$999=$G28)*('RAW_URL,PageName'!$B$2:$B$999="TY"), ""))} | O28: {=_xlfn.TEXTJOIN(CHAR(10), 1, _xlfn._xlws.FILTER('RAW_URL,PageName'!E$2:E$999, ('RAW_URL,PageName'!$C$2:$C$999=$G28)*('RAW_URL,PageName'!$B$2:$B$999="TY"), ""))} | P28: {=_xlfn.TEXTJOIN(CHAR(10), 1, _xlfn._xlws.FILTER('RAW_URL,PageName'!F$2:F$999, ('RAW_URL,PageName'!$C$2:$C$999=$G28)*('RAW_URL,PageName'!$B$2:$B$999="TY"), ""))} | Q28: {=_xlfn.TEXTJOIN(CHAR(10), 1, _xlfn._xlws.FILTER('RAW_URL,PageName'!D$2:D$999, ('RAW_URL,PageName'!$C$2:$C$999=$G28)*('RAW_URL,PageName'!$B$2:$B$999="LY"), ""))} | R28: {=_xlfn.TEXTJOIN(CHAR(10), 1, _xlfn._xlws.FILTER('RAW_URL,PageName'!E$2:E$999, ('RAW_URL,PageName'!$C$2:$C$999=$G28)*('RAW_URL,PageName'!$B$2:$B$999="LY"), ""))} | S28: {=_xlfn.TEXTJOIN(CHAR(10), 1, _xlfn._xlws.FILTER('RAW_URL,PageName'!F$2:F$999, ('RAW_URL,PageName'!$C$2:$C$999=$G28)*('RAW_URL,PageName'!$B$2:$B$999="LY"), ""))} | U28: =IFERROR(VLOOKUP($C28,태깅기획site_code!$N$4:$O$18,2,0),"") -> 2 | W28: 2 | X28: L.America | Y28: XUMCOL | Z28: Colombia | AA28: Colombia | AB28: co | AC28: 46042 | AD28: 46063 | AE28: =IF(AD28="","",IF(IF(AD28>api용!D$2,api용!D$2,AD28)<AC28,"",IF(AD28>api용!D$2,api용!D$2,AD28))) -> 46063
B29: =IF($G29="","",IFERROR(VLOOKUP($G29,RAW_tier!$B$2:$C$200,2,0),2)) -> 2 | C29: =IF(ISBLANK(태깅기획site_code!F28),"",태깅기획site_code!C28) -> EU | D29: =IF(ISBLANK(태깅기획site_code!F28),"",IF(고객법인일정파일!P28="한총","SEC",IF(LEN(TRIM(고객법인일정파일!P28))=0,태깅기획site_code!D28,고객법인일정파일!P28))) -> XADG | E29: =IF(ISBLANK(태깅기획site_code!F28),"",태깅기획site_code!E28) -> Germany | F29: =IF(ISBLANK(태깅기획site_code!F28),"",태깅기획site_code!J28) -> Germany | G29: =IF(ISBLANK(태깅기획site_code!B28),"",태깅기획site_code!F28) -> de | H29: =IF(ISBLANK(태깅기획site_code!F28),"",IF(고객법인일정파일!Q28="X","X",고객법인일정파일!R28)) -> 46031 | I29: =IF(ISBLANK(태깅기획site_code!F28),"",IF(고객법인일정파일!Q28="X","",고객법인일정파일!S28)) -> 46064 | K29: 45756 | L29: 45788 | M29: =IF(D29="","",VLOOKUP(D29,고객법인일정파일!$C$5:$J$200,8,0))&"" -> Note1-test XADG | N29: {=_xlfn.TEXTJOIN(CHAR(10), 1, _xlfn._xlws.FILTER('RAW_URL,PageName'!D$2:D$999, ('RAW_URL,PageName'!$C$2:$C$999=$G29)*('RAW_URL,PageName'!$B$2:$B$999="TY"), ""))} -> https://company_name.com/de/offer/test-campaign-2026 https://company_name.com/de/offer/test-campaign-2026-other | O29: {=_xlfn.TEXTJOIN(CHAR(10), 1, _xlfn._xlws.FILTER('RAW_URL,PageName'!E$2:E$999, ('RAW_URL,PageName'!$C$2:$C$999=$G29)*('RAW_URL,PageName'!$B$2:$B$999="TY"), ""))} -> de:offer:testcampaign2026 de:offer:testcampaign2026other | P29: {=_xlfn.TEXTJOIN(CHAR(10), 1, _xlfn._xlws.FILTER('RAW_URL,PageName'!F$2:F$999, ('RAW_URL,PageName'!$C$2:$C$999=$G29)*('RAW_URL,PageName'!$B$2:$B$999="TY"), ""))} -> 노트test1 | Q29: {=_xlfn.TEXTJOIN(CHAR(10), 1, _xlfn._xlws.FILTER('RAW_URL,PageName'!D$2:D$999, ('RAW_URL,PageName'!$C$2:$C$999=$G29)*('RAW_URL,PageName'!$B$2:$B$999="LY"), ""))} -> https://company_name.com/de/offer/test-campaign-2025 | R29: {=_xlfn.TEXTJOIN(CHAR(10), 1, _xlfn._xlws.FILTER('RAW_URL,PageName'!E$2:E$999, ('RAW_URL,PageName'!$C$2:$C$999=$G29)*('RAW_URL,PageName'!$B$2:$B$999="LY"), ""))} -> de:offer:testcampaign2025 | S29: {=_xlfn.TEXTJOIN(CHAR(10), 1, _xlfn._xlws.FILTER('RAW_URL,PageName'!F$2:F$999, ('RAW_URL,PageName'!$C$2:$C$999=$G29)*('RAW_URL,PageName'!$B$2:$B$999="LY"), ""))} -> 노트test1 | U29: =IFERROR(VLOOKUP($C29,태깅기획site_code!$N$4:$O$18,2,0),"") -> 2 | W29: 2 | X29: EU | Y29: XADCZ | Z29: Czech | AA29: Czech | AB29: cz | AC29: 46054 | AD29: 46063 | AE29: =IF(AD29="","",IF(IF(AD29>api용!D$2,api용!D$2,AD29)<AC29,"",IF(AD29>api용!D$2,api용!D$2,AD29))) -> 46063
B30: =IF($G30="","",IFERROR(VLOOKUP($G30,RAW_tier!$B$2:$C$200,2,0),2)) -> 2 | C30: =IF(ISBLANK(태깅기획site_code!F29),"",태깅기획site_code!C29) -> EU | D30: =IF(ISBLANK(태깅기획site_code!F29),"",IF(고객법인일정파일!P29="한총","SEC",IF(LEN(TRIM(고객법인일정파일!P29))=0,태깅기획site_code!D29,고객법인일정파일!P29))) -> XADNU | E30: =IF(ISBLANK(태깅기획site_code!F29),"",태깅기획site_code!E29) -> Denmark | F30: =IF(ISBLANK(태깅기획site_code!F29),"",태깅기획site_code!J29) -> Denmark | G30: =IF(ISBLANK(태깅기획site_code!B29),"",태깅기획site_code!F29) -> dk | H30: =IF(ISBLANK(태깅기획site_code!F29),"",IF(고객법인일정파일!Q29="X","X",고객법인일정파일!R29)) -> X | I30: =IF(ISBLANK(태깅기획site_code!F29),"",IF(고객법인일정파일!Q29="X","",고객법인일정파일!S29)) | K30: TBD | L30: TBD | M30: =IF(D30="","",VLOOKUP(D30,고객법인일정파일!$C$5:$J$200,8,0))&"" -> Note1-test XADBN-NL | N30: {=_xlfn.TEXTJOIN(CHAR(10), 1, _xlfn._xlws.FILTER('RAW_URL,PageName'!D$2:D$999, ('RAW_URL,PageName'!$C$2:$C$999=$G30)*('RAW_URL,PageName'!$B$2:$B$999="TY"), ""))} | O30: {=_xlfn.TEXTJOIN(CHAR(10), 1, _xlfn._xlws.FILTER('RAW_URL,PageName'!E$2:E$999, ('RAW_URL,PageName'!$C$2:$C$999=$G30)*('RAW_URL,PageName'!$B$2:$B$999="TY"), ""))} | P30: {=_xlfn.TEXTJOIN(CHAR(10), 1, _xlfn._xlws.FILTER('RAW_URL,PageName'!F$2:F$999, ('RAW_URL,PageName'!$C$2:$C$999=$G30)*('RAW_URL,PageName'!$B$2:$B$999="TY"), ""))} | Q30: {=_xlfn.TEXTJOIN(CHAR(10), 1, _xlfn._xlws.FILTER('RAW_URL,PageName'!D$2:D$999, ('RAW_URL,PageName'!$C$2:$C$999=$G30)*('RAW_URL,PageName'!$B$2:$B$999="LY"), ""))} | R30: {=_xlfn.TEXTJOIN(CHAR(10), 1, _xlfn._xlws.FILTER('RAW_URL,PageName'!E$2:E$999, ('RAW_URL,PageName'!$C$2:$C$999=$G30)*('RAW_URL,PageName'!$B$2:$B$999="LY"), ""))} | S30: {=_xlfn.TEXTJOIN(CHAR(10), 1, _xlfn._xlws.FILTER('RAW_URL,PageName'!F$2:F$999, ('RAW_URL,PageName'!$C$2:$C$999=$G30)*('RAW_URL,PageName'!$B$2:$B$999="LY"), ""))} | U30: =IFERROR(VLOOKUP($C30,태깅기획site_code!$N$4:$O$18,2,0),"") -> 2 | W30: 2 | X30: EU | Y30: XADG | Z30: Germany | AA30: Germany | AB30: de | AC30: 46031 | AD30: 46064 | AE30: =IF(AD30="","",IF(IF(AD30>api용!D$2,api용!D$2,AD30)<AC30,"",IF(AD30>api용!D$2,api용!D$2,AD30))) -> 46064
B31: =IF($G31="","",IFERROR(VLOOKUP($G31,RAW_tier!$B$2:$C$200,2,0),2)) -> 2 | C31: =IF(ISBLANK(태깅기획site_code!F30),"",태깅기획site_code!C30) -> EU | D31: =IF(ISBLANK(태깅기획site_code!F30),"",IF(고객법인일정파일!P30="한총","SEC",IF(LEN(TRIM(고객법인일정파일!P30))=0,태깅기획site_code!D30,고객법인일정파일!P30))) -> XADB | E31: =IF(ISBLANK(태깅기획site_code!F30),"",태깅기획site_code!E30) -> Estonia | F31: =IF(ISBLANK(태깅기획site_code!F30),"",태깅기획site_code!J30) -> Estonia | G31: =IF(ISBLANK(태깅기획site_code!B30),"",태깅기획site_code!F30) -> ee | H31: =IF(ISBLANK(태깅기획site_code!F30),"",IF(고객법인일정파일!Q30="X","X",고객법인일정파일!R30)) | I31: =IF(ISBLANK(태깅기획site_code!F30),"",IF(고객법인일정파일!Q30="X","",고객법인일정파일!S30)) | K31: TBD | L31: TBD | M31: =IF(D31="","",VLOOKUP(D31,고객법인일정파일!$C$5:$J$200,8,0))&"" | N31: {=_xlfn.TEXTJOIN(CHAR(10), 1, _xlfn._xlws.FILTER('RAW_URL,PageName'!D$2:D$999, ('RAW_URL,PageName'!$C$2:$C$999=$G31)*('RAW_URL,PageName'!$B$2:$B$999="TY"), ""))} | O31: {=_xlfn.TEXTJOIN(CHAR(10), 1, _xlfn._xlws.FILTER('RAW_URL,PageName'!E$2:E$999, ('RAW_URL,PageName'!$C$2:$C$999=$G31)*('RAW_URL,PageName'!$B$2:$B$999="TY"), ""))} | P31: {=_xlfn.TEXTJOIN(CHAR(10), 1, _xlfn._xlws.FILTER('RAW_URL,PageName'!F$2:F$999, ('RAW_URL,PageName'!$C$2:$C$999=$G31)*('RAW_URL,PageName'!$B$2:$B$999="TY"), ""))} | Q31: {=_xlfn.TEXTJOIN(CHAR(10), 1, _xlfn._xlws.FILTER('RAW_URL,PageName'!D$2:D$999, ('RAW_URL,PageName'!$C$2:$C$999=$G31)*('RAW_URL,PageName'!$B$2:$B$999="LY"), ""))} | R31: {=_xlfn.TEXTJOIN(CHAR(10), 1, _xlfn._xlws.FILTER('RAW_URL,PageName'!E$2:E$999, ('RAW_URL,PageName'!$C$2:$C$999=$G31)*('RAW_URL,PageName'!$B$2:$B$999="LY"), ""))} | S31: {=_xlfn.TEXTJOIN(CHAR(10), 1, _xlfn._xlws.FILTER('RAW_URL,PageName'!F$2:F$999, ('RAW_URL,PageName'!$C$2:$C$999=$G31)*('RAW_URL,PageName'!$B$2:$B$999="LY"), ""))} | U31: =IFERROR(VLOOKUP($C31,태깅기획site_code!$N$4:$O$18,2,0),"") -> 2 | W31: 2 | X31: EU | Y31: XADNU | Z31: Denmark | AA31: Denmark | AB31: dk | AC31: X | AE31: =IF(AD31="","",IF(IF(AD31>api용!D$2,api용!D$2,AD31)<AC31,"",IF(AD31>api용!D$2,api용!D$2,AD31)))
B32: =IF($G32="","",IFERROR(VLOOKUP($G32,RAW_tier!$B$2:$C$200,2,0),2)) -> 2 | C32: =IF(ISBLANK(태깅기획site_code!F31),"",태깅기획site_code!C31) -> MENA | D32: =IF(ISBLANK(태깅기획site_code!F31),"",IF(고객법인일정파일!P31="한총","SEC",IF(LEN(TRIM(고객법인일정파일!P31))=0,태깅기획site_code!D31,고객법인일정파일!P31))) -> XADADG | E32: =IF(ISBLANK(태깅기획site_code!F31),"",태깅기획site_code!E31) -> Egypt | F32: =IF(ISBLANK(태깅기획site_code!F31),"",태깅기획site_code!J31) -> Egypt | G32: =IF(ISBLANK(태깅기획site_code!B31),"",태깅기획site_code!F31) -> eg | H32: =IF(ISBLANK(태깅기획site_code!F31),"",IF(고객법인일정파일!Q31="X","X",고객법인일정파일!R31)) -> TBC | I32: =IF(ISBLANK(태깅기획site_code!F31),"",IF(고객법인일정파일!Q31="X","",고객법인일정파일!S31)) -> TBC | K32: TBD | L32: TBD | M32: =IF(D32="","",VLOOKUP(D32,고객법인일정파일!$C$5:$J$200,8,0))&"" -> Note1-test XADUX-CH | N32: {=_xlfn.TEXTJOIN(CHAR(10), 1, _xlfn._xlws.FILTER('RAW_URL,PageName'!D$2:D$999, ('RAW_URL,PageName'!$C$2:$C$999=$G32)*('RAW_URL,PageName'!$B$2:$B$999="TY"), ""))} | O32: {=_xlfn.TEXTJOIN(CHAR(10), 1, _xlfn._xlws.FILTER('RAW_URL,PageName'!E$2:E$999, ('RAW_URL,PageName'!$C$2:$C$999=$G32)*('RAW_URL,PageName'!$B$2:$B$999="TY"), ""))} | P32: {=_xlfn.TEXTJOIN(CHAR(10), 1, _xlfn._xlws.FILTER('RAW_URL,PageName'!F$2:F$999, ('RAW_URL,PageName'!$C$2:$C$999=$G32)*('RAW_URL,PageName'!$B$2:$B$999="TY"), ""))} | Q32: {=_xlfn.TEXTJOIN(CHAR(10), 1, _xlfn._xlws.FILTER('RAW_URL,PageName'!D$2:D$999, ('RAW_URL,PageName'!$C$2:$C$999=$G32)*('RAW_URL,PageName'!$B$2:$B$999="LY"), ""))} | R32: {=_xlfn.TEXTJOIN(CHAR(10), 1, _xlfn._xlws.FILTER('RAW_URL,PageName'!E$2:E$999, ('RAW_URL,PageName'!$C$2:$C$999=$G32)*('RAW_URL,PageName'!$B$2:$B$999="LY"), ""))} | S32: {=_xlfn.TEXTJOIN(CHAR(10), 1, _xlfn._xlws.FILTER('RAW_URL,PageName'!F$2:F$999, ('RAW_URL,PageName'!$C$2:$C$999=$G32)*('RAW_URL,PageName'!$B$2:$B$999="LY"), ""))} | U32: =IFERROR(VLOOKUP($C32,태깅기획site_code!$N$4:$O$18,2,0),"") -> 6 | W32: 2 | X32: MENA | Y32: XADADG | Z32: Egypt | AA32: Egypt | AB32: eg | AC32: TBC | AD32: TBC | AE32: =IF(AD32="","",IF(IF(AD32>api용!D$2,api용!D$2,AD32)<AC32,"",IF(AD32>api용!D$2,api용!D$2,AD32)))
